Workbook
Name EmpNames: '設定'!$B$8:$B$13
Name HolidayDates: '公眾假期'!$A$5:$A$84
Name HolidayNames: '公眾假期'!$B$5:$B$84
Name LeaveName: '請假登記'!$A$5:$A$504
Name LeaveDate: '請假登記'!$B$5:$B$504
Name LeaveType: '請假登記'!$C$5:$C$504
Name CompYear1: '假期上班登記'!$C$89
Name CompYear2: '假期上班登記'!$C$90
Name CompYear3: '假期上班登記'!$C$91
Name CompYear4: '假期上班登記'!$C$92
Name CompYear5: '假期上班登記'!$C$93
Name CompYear6: '假期上班登記'!$C$94

Sheet 排班表
A1: 部門輪班更表（跨年模版） | F1: 顯示年份 | G1: ='設定'!$B$3
A3: 本週／下週快覽
A4: 今天 | B4: =TODAY()
A5: 本週起始（一） | B5: =B4-WEEKDAY(B4,2)+1 | D5: 本週欄位 | E5: =IFERROR(MATCH(B5,$G$13:$BG$13,0),"非本年")
A6: 下週起始（一） | B6: =B5+7 | D6: 下週欄位 | E6: =IFERROR(MATCH(B6,$G$13:$BG$13,0),"非本年")
A8: 人員 | B8: 本週班次 | C8: 下週班次 | D8: 圖例 | E8: S | F8: A | G8: P | H8: N | I8: AL | J8: SL
A9: ='設定'!B8 | B9: =IF(OR($E$5="",$E$5="非本年"),"",IFERROR(INDEX($G14:$BG14,$E$5),"")) | C9: =IF(OR($E$6="",$E$6="非本年"),"",IFERROR(INDEX($G14:$BG14,$E$6),""))
A10: ='設定'!B9 | B10: =IF(OR($E$5="",$E$5="非本年"),"",IFERROR(INDEX($G15:$BG15,$E$5),"")) | C10: =IF(OR($E$6="",$E$6="非本年"),"",IFERROR(INDEX($G15:$BG15,$E$6),""))
A11: ='設定'!B10 | B11: =IF(OR($E$5="",$E$5="非本年"),"",IFERROR(INDEX($G16:$BG16,$E$5),"")) | C11: =IF(OR($E$6="",$E$6="非本年"),"",IFERROR(INDEX($G16:$BG16,$E$6),""))
A12: 全年排班主表｜請假請到「請假登記」逐日登錄｜補假請到「假期上班登記」｜月曆檢視見「本月排班日曆」
A13: 員工姓名 | B13: 已用年假 (本年) | C13: 剩餘年假 (本年) | D13: 累積補假 結餘 | E13: 期初補假 (可調) | F13: 本年新增 補假 | G13: =IF(((DATE('設定'!$B$3,1,1)+MOD(8-WEEKDAY(DATE('設定'!$B$3,1,1),2),7))+0*7)>DATE('設定'!$B$3,12,31),"",(DATE('設定'!$B$3,1,1)+MOD(8-WEEKDAY(DATE('設定'!$B$3,1,1),2),7))+0*7) | H13: =IF(((DATE('設定'!$B$3,1,1)+MOD(8-WEEKDAY(DATE('設定'!$B$3,1,1),2),7))+1*7)>DATE('設定'!$B$3,12,31),"",(DATE('設定'!$B$3,1,1)+MOD(8-WEEKDAY(DATE('設定'!$B$3,1,1),2),7))+1*7) | I13: =IF(((DATE('設定'!$B$3,1,1)+MOD(8-WEEKDAY(DATE('設定'!$B$3,1,1),2),7))+2*7)>DATE('設定'!$B$3,12,31),"",(DATE('設定'!$B$3,1,1)+MOD(8-WEEKDAY(DATE('設定'!$B$3,1,1),2),7))+2*7) | J13: =IF(((DATE('設定'!$B$3,1,1)+MOD(8-WEEKDAY(DATE('設定'!$B$3,1,1),2),7))+3*7)>DATE('設定'!$B$3,12,31),"",(DATE('設定'!$B$3,1,1)+MOD(8-WEEKDAY(DATE('設定'!$B$3,1,1),2),7))+3*7) | K13: =IF(((DATE('設定'!$B$3,1,1)+MOD(8-WEEKDAY(DATE('設定'!$B$3,1,1),2),7))+4*7)>DATE('設定'!$B$3,12,31),"",(DATE('設定'!$B$3,1,1)+MOD(8-WEEKDAY(DATE('設定'!$B$3,1,1),2),7))+4*7) | L13: =IF(((DATE('設定'!$B$3,1,1)+MOD(8-WEEKDAY(DATE('設定'!$B$3,1,1),2),7))+5*7)>DATE('設定'!$B$3,12,31),"",(DATE('設定'!$B$3,1,1)+MOD(8-WEEKDAY(DATE('設定'!$B$3,1,1),2),7))+5*7) | M13: =IF(((DATE('設定'!$B$3,1,1)+MOD(8-WEEKDAY(DATE('設定'!$B$3,1,1),2),7))+6*7)>DATE('設定'!$B$3,12,31),"",(DATE('設定'!$B$3,1,1)+MOD(8-WEEKDAY(DATE('設定'!$B$3,1,1),2),7))+6*7) | N13: =IF(((DATE('設定'!$B$3,1,1)+MOD(8-WEEKDAY(DATE('設定'!$B$3,1,1),2),7))+7*7)>DATE('設定'!$B$3,12,31),"",(DATE('設定'!$B$3,1,1)+MOD(8-WEEKDAY(DATE('設定'!$B$3,1,1),2),7))+7*7) | O13: =IF(((DATE('設定'!$B$3,1,1)+MOD(8-WEEKDAY(DATE('設定'!$B$3,1,1),2),7))+8*7)>DATE('設定'!$B$3,12,31),"",(DATE('設定'!$B$3,1,1)+MOD(8-WEEKDAY(DATE('設定'!$B$3,1,1),2),7))+8*7) | P13: =IF(((DATE('設定'!$B$3,1,1)+MOD(8-WEEKDAY(DATE('設定'!$B$3,1,1),2),7))+9*7)>DATE('設定'!$B$3,12,31),"",(DATE('設定'!$B$3,1,1)+MOD(8-WEEKDAY(DATE('設定'!$B$3,1,1),2),7))+9*7) | Q13: =IF(((DATE('設定'!$B$3,1,1)+MOD(8-WEEKDAY(DATE('設定'!$B$3,1,1),2),7))+10*7)>DATE('設定'!$B$3,12,31),"",(DATE('設定'!$B$3,1,1)+MOD(8-WEEKDAY(DATE('設定'!$B$3,1,1),2),7))+10*7) | R13: =IF(((DATE('設定'!$B$3,1,1)+MOD(8-WEEKDAY(DATE('設定'!$B$3,1,1),2),7))+11*7)>DATE('設定'!$B$3,12,31),"",(DATE('設定'!$B$3,1,1)+MOD(8-WEEKDAY(DATE('設定'!$B$3,1,1),2),7))+11*7) | S13: =IF(((DATE('設定'!$B$3,1,1)+MOD(8-WEEKDAY(DATE('設定'!$B$3,1,1),2),7))+12*7)>DATE('設定'!$B$3,12,31),"",(DATE('設定'!$B$3,1,1)+MOD(8-WEEKDAY(DATE('設定'!$B$3,1,1),2),7))+12*7) | T13: =IF(((DATE('設定'!$B$3,1,1)+MOD(8-WEEKDAY(DATE('設定'!$B$3,1,1),2),7))+13*7)>DATE('設定'!$B$3,12,31),"",(DATE('設定'!$B$3,1,1)+MOD(8-WEEKDAY(DATE('設定'!$B$3,1,1),2),7))+13*7) | U13: =IF(((DATE('設定'!$B$3,1,1)+MOD(8-WEEKDAY(DATE('設定'!$B$3,1,1),2),7))+14*7)>DATE('設定'!$B$3,12,31),"",(DATE('設定'!$B$3,1,1)+MOD(8-WEEKDAY(DATE('設定'!$B$3,1,1),2),7))+14*7) | V13: =IF(((DATE('設定'!$B$3,1,1)+MOD(8-WEEKDAY(DATE('設定'!$B$3,1,1),2),7))+15*7)>DATE('設定'!$B$3,12,31),"",(DATE('設定'!$B$3,1,1)+MOD(8-WEEKDAY(DATE('設定'!$B$3,1,1),2),7))+15*7) | W13: =IF(((DATE('設定'!$B$3,1,1)+MOD(8-WEEKDAY(DATE('設定'!$B$3,1,1),2),7))+16*7)>DATE('設定'!$B$3,12,31),"",(DATE('設定'!$B$3,1,1)+MOD(8-WEEKDAY(DATE('設定'!$B$3,1,1),2),7))+16*7) | X13: =IF(((DATE('設定'!$B$3,1,1)+MOD(8-WEEKDAY(DATE('設定'!$B$3,1,1),2),7))+17*7)>DATE('設定'!$B$3,12,31),"",(DATE('設定'!$B$3,1,1)+MOD(8-WEEKDAY(DATE('設定'!$B$3,1,1),2),7))+17*7) | Y13: =IF(((DATE('設定'!$B$3,1,1)+MOD(8-WEEKDAY(DATE('設定'!$B$3,1,1),2),7))+18*7)>DATE('設定'!$B$3,12,31),"",(DATE('設定'!$B$3,1,1)+MOD(8-WEEKDAY(DATE('設定'!$B$3,1,1),2),7))+18*7) | Z13: =IF(((DATE('設定'!$B$3,1,1)+MOD(8-WEEKDAY(DATE('設定'!$B$3,1,1),2),7))+19*7)>DATE('設定'!$B$3,12,31),"",(DATE('設定'!$B$3,1,1)+MOD(8-WEEKDAY(DATE('設定'!$B$3,1,1),2),7))+19*7) | AA13: =IF(((DATE('設定'!$B$3,1,1)+MOD(8-WEEKDAY(DATE('設定'!$B$3,1,1),2),7))+20*7)>DATE('設定'!$B$3,12,31),"",(DATE('設定'!$B$3,1,1)+MOD(8-WEEKDAY(DATE('設定'!$B$3,1,1),2),7))+20*7) | AB13: =IF(((DATE('設定'!$B$3,1,1)+MOD(8-WEEKDAY(DATE('設定'!$B$3,1,1),2),7))+21*7)>DATE('設定'!$B$3,12,31),"",(DATE('設定'!$B$3,1,1)+MOD(8-WEEKDAY(DATE('設定'!$B$3,1,1),2),7))+21*7) | AC13: =IF(((DATE('設定'!$B$3,1,1)+MOD(8-WEEKDAY(DATE('設定'!$B$3,1,1),2),7))+22*7)>DATE('設定'!$B$3,12,31),"",(DATE('設定'!$B$3,1,1)+MOD(8-WEEKDAY(DATE('設定'!$B$3,1,1),2),7))+22*7) | AD13: =IF(((DATE('設定'!$B$3,1,1)+MOD(8-WEEKDAY(DATE('設定'!$B$3,1,1),2),7))+23*7)>DATE('設定'!$B$3,12,31),"",(DATE('設定'!$B$3,1,1)+MOD(8-WEEKDAY(DATE('設定'!$B$3,1,1),2),7))+23*7) | AE13: =IF(((DATE('設定'!$B$3,1,1)+MOD(8-WEEKDAY(DATE('設定'!$B$3,1,1),2),7))+24*7)>DATE('設定'!$B$3,12,31),"",(DATE('設定'!$B$3,1,1)+MOD(8-WEEKDAY(DATE('設定'!$B$3,1,1),2),7))+24*7) | AF13: =IF(((DATE('設定'!$B$3,1,1)+MOD(8-WEEKDAY(DATE('設定'!$B$3,1,1),2),7))+25*7)>DATE('設定'!$B$3,12,31),"",(DATE('設定'!$B$3,1,1)+MOD(8-WEEKDAY(DATE('設定'!$B$3,1,1),2),7))+25*7) | AG13: =IF(((DATE('設定'!$B$3,1,1)+MOD(8-WEEKDAY(DATE('設定'!$B$3,1,1),2),7))+26*7)>DATE('設定'!$B$3,12,31),"",(DATE('設定'!$B$3,1,1)+MOD(8-WEEKDAY(DATE('設定'!$B$3,1,1),2),7))+26*7) | AH13: =IF(((DATE('設定'!$B$3,1,1)+MOD(8-WEEKDAY(DATE('設定'!$B$3,1,1),2),7))+27*7)>DATE('設定'!$B$3,12,31),"",(DATE('設定'!$B$3,1,1)+MOD(8-WEEKDAY(DATE('設定'!$B$3,1,1),2),7))+27*7) | AI13: =IF(((DATE('設定'!$B$3,1,1)+MOD(8-WEEKDAY(DATE('設定'!$B$3,1,1),2),7))+28*7)>DATE('設定'!$B$3,12,31),"",(DATE('設定'!$B$3,1,1)+MOD(8-WEEKDAY(DATE('設定'!$B$3,1,1),2),7))+28*7) | AJ13: =IF(((DATE('設定'!$B$3,1,1)+MOD(8-WEEKDAY(DATE('設定'!$B$3,1,1),2),7))+29*7)>DATE('設定'!$B$3,12,31),"",(DATE('設定'!$B$3,1,1)+MOD(8-WEEKDAY(DATE('設定'!$B$3,1,1),2),7))+29*7) | AK13: =IF(((DATE('設定'!$B$3,1,1)+MOD(8-WEEKDAY(DATE('設定'!$B$3,1,1),2),7))+30*7)>DATE('設定'!$B$3,12,31),"",(DATE('設定'!$B$3,1,1)+MOD(8-WEEKDAY(DATE('設定'!$B$3,1,1),2),7))+30*7) | AL13: =IF(((DATE('設定'!$B$3,1,1)+MOD(8-WEEKDAY(DATE('設定'!$B$3,1,1),2),7))+31*7)>DATE('設定'!$B$3,12,31),"",(DATE('設定'!$B$3,1,1)+MOD(8-WEEKDAY(DATE('設定'!$B$3,1,1),2),7))+31*7) | AM13: =IF(((DATE('設定'!$B$3,1,1)+MOD(8-WEEKDAY(DATE('設定'!$B$3,1,1),2),7))+32*7)>DATE('設定'!$B$3,12,31),"",(DATE('設定'!$B$3,1,1)+MOD(8-WEEKDAY(DATE('設定'!$B$3,1,1),2),7))+32*7) | AN13: =IF(((DATE('設定'!$B$3,1,1)+MOD(8-WEEKDAY(DATE('設定'!$B$3,1,1),2),7))+33*7)>DATE('設定'!$B$3,12,31),"",(DATE('設定'!$B$3,1,1)+MOD(8-WEEKDAY(DATE('設定'!$B$3,1,1),2),7))+33*7) | AO13: =IF(((DATE('設定'!$B$3,1,1)+MOD(8-WEEKDAY(DATE('設定'!$B$3,1,1),2),7))+34*7)>DATE('設定'!$B$3,12,31),"",(DATE('設定'!$B$3,1,1)+MOD(8-WEEKDAY(DATE('設定'!$B$3,1,1),2),7))+34*7) | AP13: =IF(((DATE('設定'!$B$3,1,1)+MOD(8-WEEKDAY(DATE('設定'!$B$3,1,1),2),7))+35*7)>DATE('設定'!$B$3,12,31),"",(DATE('設定'!$B$3,1,1)+MOD(8-WEEKDAY(DATE('設定'!$B$3,1,1),2),7))+35*7) | AQ13: =IF(((DATE('設定'!$B$3,1,1)+MOD(8-WEEKDAY(DATE('設定'!$B$3,1,1),2),7))+36*7)>DATE('設定'!$B$3,12,31),"",(DATE('設定'!$B$3,1,1)+MOD(8-WEEKDAY(DATE('設定'!$B$3,1,1),2),7))+36*7) | AR13: =IF(((DATE('設定'!$B$3,1,1)+MOD(8-WEEKDAY(DATE('設定'!$B$3,1,1),2),7))+37*7)>DATE('設定'!$B$3,12,31),"",(DATE('設定'!$B$3,1,1)+MOD(8-WEEKDAY(DATE('設定'!$B$3,1,1),2),7))+37*7) | AS13: =IF(((DATE('設定'!$B$3,1,1)+MOD(8-WEEKDAY(DATE('設定'!$B$3,1,1),2),7))+38*7)>DATE('設定'!$B$3,12,31),"",(DATE('設定'!$B$3,1,1)+MOD(8-WEEKDAY(DATE('設定'!$B$3,1,1),2),7))+38*7) | AT13: =IF(((DATE('設定'!$B$3,1,1)+MOD(8-WEEKDAY(DATE('設定'!$B$3,1,1),2),7))+39*7)>DATE('設定'!$B$3,12,31),"",(DATE('設定'!$B$3,1,1)+MOD(8-WEEKDAY(DATE('設定'!$B$3,1,1),2),7))+39*7) | AU13: =IF(((DATE('設定'!$B$3,1,1)+MOD(8-WEEKDAY(DATE('設定'!$B$3,1,1),2),7))+40*7)>DATE('設定'!$B$3,12,31),"",(DATE('設定'!$B$3,1,1)+MOD(8-WEEKDAY(DATE('設定'!$B$3,1,1),2),7))+40*7) | AV13: =IF(((DATE('設定'!$B$3,1,1)+MOD(8-WEEKDAY(DATE('設定'!$B$3,1,1),2),7))+41*7)>DATE('設定'!$B$3,12,31),"",(DATE('設定'!$B$3,1,1)+MOD(8-WEEKDAY(DATE('設定'!$B$3,1,1),2),7))+41*7) | AW13: =IF(((DATE('設定'!$B$3,1,1)+MOD(8-WEEKDAY(DATE('設定'!$B$3,1,1),2),7))+42*7)>DATE('設定'!$B$3,12,31),"",(DATE('設定'!$B$3,1,1)+MOD(8-WEEKDAY(DATE('設定'!$B$3,1,1),2),7))+42*7) | AX13: =IF(((DATE('設定'!$B$3,1,1)+MOD(8-WEEKDAY(DATE('設定'!$B$3,1,1),2),7))+43*7)>DATE('設定'!$B$3,12,31),"",(DATE('設定'!$B$3,1,1)+MOD(8-WEEKDAY(DATE('設定'!$B$3,1,1),2),7))+43*7) | AY13: =IF(((DATE('設定'!$B$3,1,1)+MOD(8-WEEKDAY(DATE('設定'!$B$3,1,1),2),7))+44*7)>DATE('設定'!$B$3,12,31),"",(DATE('設定'!$B$3,1,1)+MOD(8-WEEKDAY(DATE('設定'!$B$3,1,1),2),7))+44*7) | AZ13: =IF(((DATE('設定'!$B$3,1,1)+MOD(8-WEEKDAY(DATE('設定'!$B$3,1,1),2),7))+45*7)>DATE('設定'!$B$3,12,31),"",(DATE('設定'!$B$3,1,1)+MOD(8-WEEKDAY(DATE('設定'!$B$3,1,1),2),7))+45*7) | BA13: =IF(((DATE('設定'!$B$3,1,1)+MOD(8-WEEKDAY(DATE('設定'!$B$3,1,1),2),7))+46*7)>DATE('設定'!$B$3,12,31),"",(DATE('設定'!$B$3,1,1)+MOD(8-WEEKDAY(DATE('設定'!$B$3,1,1),2),7))+46*7) | BB13: =IF(((DATE('設定'!$B$3,1,1)+MOD(8-WEEKDAY(DATE('設定'!$B$3,1,1),2),7))+47*7)>DATE('設定'!$B$3,12,31),"",(DATE('設定'!$B$3,1,1)+MOD(8-WEEKDAY(DATE('設定'!$B$3,1,1),2),7))+47*7) | BC13: =IF(((DATE('設定'!$B$3,1,1)+MOD(8-WEEKDAY(DATE('設定'!$B$3,1,1),2),7))+48*7)>DATE('設定'!$B$3,12,31),"",(DATE('設定'!$B$3,1,1)+MOD(8-WEEKDAY(DATE('設定'!$B$3,1,1),2),7))+48*7) | BD13: =IF(((DATE('設定'!$B$3,1,1)+MOD(8-WEEKDAY(DATE('設定'!$B$3,1,1),2),7))+49*7)>DATE('設定'!$B$3,12,31),"",(DATE('設定'!$B$3,1,1)+MOD(8-WEEKDAY(DATE('設定'!$B$3,1,1),2),7))+49*7) | BE13: =IF(((DATE('設定'!$B$3,1,1)+MOD(8-WEEKDAY(DATE('設定'!$B$3,1,1),2),7))+50*7)>DATE('設定'!$B$3,12,31),"",(DATE('設定'!$B$3,1,1)+MOD(8-WEEKDAY(DATE('設定'!$B$3,1,1),2),7))+50*7) | BF13: =IF(((DATE('設定'!$B$3,1,1)+MOD(8-WEEKDAY(DATE('設定'!$B$3,1,1),2),7))+51*7)>DATE('設定'!$B$3,12,31),"",(DATE('設定'!$B$3,1,1)+MOD(8-WEEKDAY(DATE('設定'!$B$3,1,1),2),7))+51*7) | BG13: =IF(((DATE('設定'!$B$3,1,1)+MOD(8-WEEKDAY(DATE('設定'!$B$3,1,1),2),7))+52*7)>DATE('設定'!$B$3,12,31),"",(DATE('設定'!$B$3,1,1)+MOD(8-WEEKDAY(DATE('設定'!$B$3,1,1),2),7))+52*7)
A14: ='設定'!B8 | B14: =IF(A14="","",COUNTIFS(LeaveName,A14,LeaveType,"AL",LeaveDate,">="&DATE('設定'!$B$3,1,1),LeaveDate,"<="&DATE('設定'!$B$3,12,31))) | C14: =IF(A14="","",IF('設定'!E8="","",'設定'!E8-B14)) | D14: =IF(A14="","",E14+F14) | E14: 0 | F14: =IF(A14="","",CompYear1) | G14: =IF(G$13="","",IF('設定'!$B$8="","",IF(COUNTIFS(LeaveName,'設定'!$B$8,LeaveType,"AL",LeaveDate,">="&G$13,LeaveDate,"<"&G$13+7)>0,"AL",IF(COUNTIFS(LeaveName,'設定'!$B$8,LeaveType,"SL",LeaveDate,">="&G$13,LeaveDate,"<"&G$13+7)>0,"SL",IF('設定'!$C$8="S","S",IF('設定'!$C$8="R",IF(MOD(INT((G$13-'設定'!$B$4)/7)+IF('設定'!$D$8="",0,'設定'!$D$8),16)<4,"A",IF(MOD(INT((G$13-'設定'!$B$4)/7)+IF('設定'!$D$8="",0,'設定'!$D$8),16)<8,"P",IF(MOD(INT((G$13-'設定'!$B$4)/7)+IF('設定'!$D$8="",0,'設定'!$D$8),16)<12,"N","P"))),"")))))) | H14: =IF(H$13="","",IF('設定'!$B$8="","",IF(COUNTIFS(LeaveName,'設定'!$B$8,LeaveType,"AL",LeaveDate,">="&H$13,LeaveDate,"<"&H$13+7)>0,"AL",IF(COUNTIFS(LeaveName,'設定'!$B$8,LeaveType,"SL",LeaveDate,">="&H$13,LeaveDate,"<"&H$13+7)>0,"SL",IF('設定'!$C$8="S","S",IF('設定'!$C$8="R",IF(MOD(INT((H$13-'設定'!$B$4)/7)+IF('設定'!$D$8="",0,'設定'!$D$8),16)<4,"A",IF(MOD(INT((H$13-'設定'!$B$4)/7)+IF('設定'!$D$8="",0,'設定'!$D$8),16)<8,"P",IF(MOD(INT((H$13-'設定'!$B$4)/7)+IF('設定'!$D$8="",0,'設定'!$D$8),16)<12,"N","P"))),"")))))) | I14: =IF(I$13="","",IF('設定'!$B$8="","",IF(COUNTIFS(LeaveName,'設定'!$B$8,LeaveType,"AL",LeaveDate,">="&I$13,LeaveDate,"<"&I$13+7)>0,"AL",IF(COUNTIFS(LeaveName,'設定'!$B$8,LeaveType,"SL",LeaveDate,">="&I$13,LeaveDate,"<"&I$13+7)>0,"SL",IF('設定'!$C$8="S","S",IF('設定'!$C$8="R",IF(MOD(INT((I$13-'設定'!$B$4)/7)+IF('設定'!$D$8="",0,'設定'!$D$8),16)<4,"A",IF(MOD(INT((I$13-'設定'!$B$4)/7)+IF('設定'!$D$8="",0,'設定'!$D$8),16)<8,"P",IF(MOD(INT((I$13-'設定'!$B$4)/7)+IF('設定'!$D$8="",0,'設定'!$D$8),16)<12,"N","P"))),"")))))) | J14: =IF(J$13="","",IF('設定'!$B$8="","",IF(COUNTIFS(LeaveName,'設定'!$B$8,LeaveType,"AL",LeaveDate,">="&J$13,LeaveDate,"<"&J$13+7)>0,"AL",IF(COUNTIFS(LeaveName,'設定'!$B$8,LeaveType,"SL",LeaveDate,">="&J$13,LeaveDate,"<"&J$13+7)>0,"SL",IF('設定'!$C$8="S","S",IF('設定'!$C$8="R",IF(MOD(INT((J$13-'設定'!$B$4)/7)+IF('設定'!$D$8="",0,'設定'!$D$8),16)<4,"A",IF(MOD(INT((J$13-'設定'!$B$4)/7)+IF('設定'!$D$8="",0,'設定'!$D$8),16)<8,"P",IF(MOD(INT((J$13-'設定'!$B$4)/7)+IF('設定'!$D$8="",0,'設定'!$D$8),16)<12,"N","P"))),"")))))) | K14: =IF(K$13="","",IF('設定'!$B$8="","",IF(COUNTIFS(LeaveName,'設定'!$B$8,LeaveType,"AL",LeaveDate,">="&K$13,LeaveDate,"<"&K$13+7)>0,"AL",IF(COUNTIFS(LeaveName,'設定'!$B$8,LeaveType,"SL",LeaveDate,">="&K$13,LeaveDate,"<"&K$13+7)>0,"SL",IF('設定'!$C$8="S","S",IF('設定'!$C$8="R",IF(MOD(INT((K$13-'設定'!$B$4)/7)+IF('設定'!$D$8="",0,'設定'!$D$8),16)<4,"A",IF(MOD(INT((K$13-'設定'!$B$4)/7)+IF('設定'!$D$8="",0,'設定'!$D$8),16)<8,"P",IF(MOD(INT((K$13-'設定'!$B$4)/7)+IF('設定'!$D$8="",0,'設定'!$D$8),16)<12,"N","P"))),"")))))) | L14: =IF(L$13="","",IF('設定'!$B$8="","",IF(COUNTIFS(LeaveName,'設定'!$B$8,LeaveType,"AL",LeaveDate,">="&L$13,LeaveDate,"<"&L$13+7)>0,"AL",IF(COUNTIFS(LeaveName,'設定'!$B$8,LeaveType,"SL",LeaveDate,">="&L$13,LeaveDate,"<"&L$13+7)>0,"SL",IF('設定'!$C$8="S","S",IF('設定'!$C$8="R",IF(MOD(INT((L$13-'設定'!$B$4)/7)+IF('設定'!$D$8="",0,'設定'!$D$8),16)<4,"A",IF(MOD(INT((L$13-'設定'!$B$4)/7)+IF('設定'!$D$8="",0,'設定'!$D$8),16)<8,"P",IF(MOD(INT((L$13-'設定'!$B$4)/7)+IF('設定'!$D$8="",0,'設定'!$D$8),16)<12,"N","P"))),"")))))) | M14: =IF(M$13="","",IF('設定'!$B$8="","",IF(COUNTIFS(LeaveName,'設定'!$B$8,LeaveType,"AL",LeaveDate,">="&M$13,LeaveDate,"<"&M$13+7)>0,"AL",IF(COUNTIFS(LeaveName,'設定'!$B$8,LeaveType,"SL",LeaveDate,">="&M$13,LeaveDate,"<"&M$13+7)>0,"SL",IF('設定'!$C$8="S","S",IF('設定'!$C$8="R",IF(MOD(INT((M$13-'設定'!$B$4)/7)+IF('設定'!$D$8="",0,'設定'!$D$8),16)<4,"A",IF(MOD(INT((M$13-'設定'!$B$4)/7)+IF('設定'!$D$8="",0,'設定'!$D$8),16)<8,"P",IF(MOD(INT((M$13-'設定'!$B$4)/7)+IF('設定'!$D$8="",0,'設定'!$D$8),16)<12,"N","P"))),"")))))) | N14: =IF(N$13="","",IF('設定'!$B$8="","",IF(COUNTIFS(LeaveName,'設定'!$B$8,LeaveType,"AL",LeaveDate,">="&N$13,LeaveDate,"<"&N$13+7)>0,"AL",IF(COUNTIFS(LeaveName,'設定'!$B$8,LeaveType,"SL",LeaveDate,">="&N$13,LeaveDate,"<"&N$13+7)>0,"SL",IF('設定'!$C$8="S","S",IF('設定'!$C$8="R",IF(MOD(INT((N$13-'設定'!$B$4)/7)+IF('設定'!$D$8="",0,'設定'!$D$8),16)<4,"A",IF(MOD(INT((N$13-'設定'!$B$4)/7)+IF('設定'!$D$8="",0,'設定'!$D$8),16)<8,"P",IF(MOD(INT((N$13-'設定'!$B$4)/7)+IF('設定'!$D$8="",0,'設定'!$D$8),16)<12,"N","P"))),"")))))) | ... BG14: =IF(BG$13="","",IF('設定'!$B$8="","",IF(COUNTIFS(LeaveName,'設定'!$B$8,LeaveType,"AL",LeaveDate,">="&BG$13,LeaveDate,"<"&BG$13+7)>0,"AL",IF(COUNTIFS(LeaveName,'設定'!$B$8,LeaveType,"SL",LeaveDate,">="&BG$13,LeaveDate,"<"&BG$13+7)>0,"SL",IF('設定'!$C$8="S","S",IF('設定'!$C$8="R",IF(MOD(INT((BG$13-'設定'!$B$4)/7)+IF('設定'!$D$8="",0,'設定'!$D$8),16)<4,"A",IF(MOD(INT((BG$13-'設定'!$B$4)/7)+IF('設定'!$D$8="",0,'設定'!$D$8),16)<8,"P",IF(MOD(INT((BG$13-'設定'!$B$4)/7)+IF('設定'!$D$8="",0,'設定'!$D$8),16)<12,"N","P"))),""))))))
A15: ='設定'!B9 | B15: =IF(A15="","",COUNTIFS(LeaveName,A15,LeaveType,"AL",LeaveDate,">="&DATE('設定'!$B$3,1,1),LeaveDate,"<="&DATE('設定'!$B$3,12,31))) | C15: =IF(A15="","",IF('設定'!E9="","",'設定'!E9-B15)) | D15: =IF(A15="","",E15+F15) | E15: 0 | F15: =IF(A15="","",CompYear2) | G15: =IF(G$13="","",IF('設定'!$B$9="","",IF(COUNTIFS(LeaveName,'設定'!$B$9,LeaveType,"AL",LeaveDate,">="&G$13,LeaveDate,"<"&G$13+7)>0,"AL",IF(COUNTIFS(LeaveName,'設定'!$B$9,LeaveType,"SL",LeaveDate,">="&G$13,LeaveDate,"<"&G$13+7)>0,"SL",IF('設定'!$C$9="S","S",IF('設定'!$C$9="R",IF(MOD(INT((G$13-'設定'!$B$4)/7)+IF('設定'!$D$9="",0,'設定'!$D$9),16)<4,"A",IF(MOD(INT((G$13-'設定'!$B$4)/7)+IF('設定'!$D$9="",0,'設定'!$D$9),16)<8,"P",IF(MOD(INT((G$13-'設定'!$B$4)/7)+IF('設定'!$D$9="",0,'設定'!$D$9),16)<12,"N","P"))),"")))))) | H15: =IF(H$13="","",IF('設定'!$B$9="","",IF(COUNTIFS(LeaveName,'設定'!$B$9,LeaveType,"AL",LeaveDate,">="&H$13,LeaveDate,"<"&H$13+7)>0,"AL",IF(COUNTIFS(LeaveName,'設定'!$B$9,LeaveType,"SL",LeaveDate,">="&H$13,LeaveDate,"<"&H$13+7)>0,"SL",IF('設定'!$C$9="S","S",IF('設定'!$C$9="R",IF(MOD(INT((H$13-'設定'!$B$4)/7)+IF('設定'!$D$9="",0,'設定'!$D$9),16)<4,"A",IF(MOD(INT((H$13-'設定'!$B$4)/7)+IF('設定'!$D$9="",0,'設定'!$D$9),16)<8,"P",IF(MOD(INT((H$13-'設定'!$B$4)/7)+IF('設定'!$D$9="",0,'設定'!$D$9),16)<12,"N","P"))),"")))))) | I15: =IF(I$13="","",IF('設定'!$B$9="","",IF(COUNTIFS(LeaveName,'設定'!$B$9,LeaveType,"AL",LeaveDate,">="&I$13,LeaveDate,"<"&I$13+7)>0,"AL",IF(COUNTIFS(LeaveName,'設定'!$B$9,LeaveType,"SL",LeaveDate,">="&I$13,LeaveDate,"<"&I$13+7)>0,"SL",IF('設定'!$C$9="S","S",IF('設定'!$C$9="R",IF(MOD(INT((I$13-'設定'!$B$4)/7)+IF('設定'!$D$9="",0,'設定'!$D$9),16)<4,"A",IF(MOD(INT((I$13-'設定'!$B$4)/7)+IF('設定'!$D$9="",0,'設定'!$D$9),16)<8,"P",IF(MOD(INT((I$13-'設定'!$B$4)/7)+IF('設定'!$D$9="",0,'設定'!$D$9),16)<12,"N","P"))),"")))))) | J15: =IF(J$13="","",IF('設定'!$B$9="","",IF(COUNTIFS(LeaveName,'設定'!$B$9,LeaveType,"AL",LeaveDate,">="&J$13,LeaveDate,"<"&J$13+7)>0,"AL",IF(COUNTIFS(LeaveName,'設定'!$B$9,LeaveType,"SL",LeaveDate,">="&J$13,LeaveDate,"<"&J$13+7)>0,"SL",IF('設定'!$C$9="S","S",IF('設定'!$C$9="R",IF(MOD(INT((J$13-'設定'!$B$4)/7)+IF('設定'!$D$9="",0,'設定'!$D$9),16)<4,"A",IF(MOD(INT((J$13-'設定'!$B$4)/7)+IF('設定'!$D$9="",0,'設定'!$D$9),16)<8,"P",IF(MOD(INT((J$13-'設定'!$B$4)/7)+IF('設定'!$D$9="",0,'設定'!$D$9),16)<12,"N","P"))),"")))))) | K15: =IF(K$13="","",IF('設定'!$B$9="","",IF(COUNTIFS(LeaveName,'設定'!$B$9,LeaveType,"AL",LeaveDate,">="&K$13,LeaveDate,"<"&K$13+7)>0,"AL",IF(COUNTIFS(LeaveName,'設定'!$B$9,LeaveType,"SL",LeaveDate,">="&K$13,LeaveDate,"<"&K$13+7)>0,"SL",IF('設定'!$C$9="S","S",IF('設定'!$C$9="R",IF(MOD(INT((K$13-'設定'!$B$4)/7)+IF('設定'!$D$9="",0,'設定'!$D$9),16)<4,"A",IF(MOD(INT((K$13-'設定'!$B$4)/7)+IF('設定'!$D$9="",0,'設定'!$D$9),16)<8,"P",IF(MOD(INT((K$13-'設定'!$B$4)/7)+IF('設定'!$D$9="",0,'設定'!$D$9),16)<12,"N","P"))),"")))))) | L15: =IF(L$13="","",IF('設定'!$B$9="","",IF(COUNTIFS(LeaveName,'設定'!$B$9,LeaveType,"AL",LeaveDate,">="&L$13,LeaveDate,"<"&L$13+7)>0,"AL",IF(COUNTIFS(LeaveName,'設定'!$B$9,LeaveType,"SL",LeaveDate,">="&L$13,LeaveDate,"<"&L$13+7)>0,"SL",IF('設定'!$C$9="S","S",IF('設定'!$C$9="R",IF(MOD(INT((L$13-'設定'!$B$4)/7)+IF('設定'!$D$9="",0,'設定'!$D$9),16)<4,"A",IF(MOD(INT((L$13-'設定'!$B$4)/7)+IF('設定'!$D$9="",0,'設定'!$D$9),16)<8,"P",IF(MOD(INT((L$13-'設定'!$B$4)/7)+IF('設定'!$D$9="",0,'設定'!$D$9),16)<12,"N","P"))),"")))))) | M15: =IF(M$13="","",IF('設定'!$B$9="","",IF(COUNTIFS(LeaveName,'設定'!$B$9,LeaveType,"AL",LeaveDate,">="&M$13,LeaveDate,"<"&M$13+7)>0,"AL",IF(COUNTIFS(LeaveName,'設定'!$B$9,LeaveType,"SL",LeaveDate,">="&M$13,LeaveDate,"<"&M$13+7)>0,"SL",IF('設定'!$C$9="S","S",IF('設定'!$C$9="R",IF(MOD(INT((M$13-'設定'!$B$4)/7)+IF('設定'!$D$9="",0,'設定'!$D$9),16)<4,"A",IF(MOD(INT((M$13-'設定'!$B$4)/7)+IF('設定'!$D$9="",0,'設定'!$D$9),16)<8,"P",IF(MOD(INT((M$13-'設定'!$B$4)/7)+IF('設定'!$D$9="",0,'設定'!$D$9),16)<12,"N","P"))),"")))))) | N15: =IF(N$13="","",IF('設定'!$B$9="","",IF(COUNTIFS(LeaveName,'設定'!$B$9,LeaveType,"AL",LeaveDate,">="&N$13,LeaveDate,"<"&N$13+7)>0,"AL",IF(COUNTIFS(LeaveName,'設定'!$B$9,LeaveType,"SL",LeaveDate,">="&N$13,LeaveDate,"<"&N$13+7)>0,"SL",IF('設定'!$C$9="S","S",IF('設定'!$C$9="R",IF(MOD(INT((N$13-'設定'!$B$4)/7)+IF('設定'!$D$9="",0,'設定'!$D$9),16)<4,"A",IF(MOD(INT((N$13-'設定'!$B$4)/7)+IF('設定'!$D$9="",0,'設定'!$D$9),16)<8,"P",IF(MOD(INT((N$13-'設定'!$B$4)/7)+IF('設定'!$D$9="",0,'設定'!$D$9),16)<12,"N","P"))),"")))))) | ... BG15: =IF(BG$13="","",IF('設定'!$B$9="","",IF(COUNTIFS(LeaveName,'設定'!$B$9,LeaveType,"AL",LeaveDate,">="&BG$13,LeaveDate,"<"&BG$13+7)>0,"AL",IF(COUNTIFS(LeaveName,'設定'!$B$9,LeaveType,"SL",LeaveDate,">="&BG$13,LeaveDate,"<"&BG$13+7)>0,"SL",IF('設定'!$C$9="S","S",IF('設定'!$C$9="R",IF(MOD(INT((BG$13-'設定'!$B$4)/7)+IF('設定'!$D$9="",0,'設定'!$D$9),16)<4,"A",IF(MOD(INT((BG$13-'設定'!$B$4)/7)+IF('設定'!$D$9="",0,'設定'!$D$9),16)<8,"P",IF(MOD(INT((BG$13-'設定'!$B$4)/7)+IF('設定'!$D$9="",0,'設定'!$D$9),16)<12,"N","P"))),""))))))
A16: ='設定'!B10 | B16: =IF(A16="","",COUNTIFS(LeaveName,A16,LeaveType,"AL",LeaveDate,">="&DATE('設定'!$B$3,1,1),LeaveDate,"<="&DATE('設定'!$B$3,12,31))) | C16: =IF(A16="","",IF('設定'!E10="","",'設定'!E10-B16)) | D16: =IF(A16="","",E16+F16) | E16: 0 | F16: =IF(A16="","",CompYear3) | G16: =IF(G$13="","",IF('設定'!$B$10="","",IF(COUNTIFS(LeaveName,'設定'!$B$10,LeaveType,"AL",LeaveDate,">="&G$13,LeaveDate,"<"&G$13+7)>0,"AL",IF(COUNTIFS(LeaveName,'設定'!$B$10,LeaveType,"SL",LeaveDate,">="&G$13,LeaveDate,"<"&G$13+7)>0,"SL",IF('設定'!$C$10="S","S",IF('設定'!$C$10="R",IF(MOD(INT((G$13-'設定'!$B$4)/7)+IF('設定'!$D$10="",0,'設定'!$D$10),16)<4,"A",IF(MOD(INT((G$13-'設定'!$B$4)/7)+IF('設定'!$D$10="",0,'設定'!$D$10),16)<8,"P",IF(MOD(INT((G$13-'設定'!$B$4)/7)+IF('設定'!$D$10="",0,'設定'!$D$10),16)<12,"N","P"))),"")))))) | H16: =IF(H$13="","",IF('設定'!$B$10="","",IF(COUNTIFS(LeaveName,'設定'!$B$10,LeaveType,"AL",LeaveDate,">="&H$13,LeaveDate,"<"&H$13+7)>0,"AL",IF(COUNTIFS(LeaveName,'設定'!$B$10,LeaveType,"SL",LeaveDate,">="&H$13,LeaveDate,"<"&H$13+7)>0,"SL",IF('設定'!$C$10="S","S",IF('設定'!$C$10="R",IF(MOD(INT((H$13-'設定'!$B$4)/7)+IF('設定'!$D$10="",0,'設定'!$D$10),16)<4,"A",IF(MOD(INT((H$13-'設定'!$B$4)/7)+IF('設定'!$D$10="",0,'設定'!$D$10),16)<8,"P",IF(MOD(INT((H$13-'設定'!$B$4)/7)+IF('設定'!$D$10="",0,'設定'!$D$10),16)<12,"N","P"))),"")))))) | I16: =IF(I$13="","",IF('設定'!$B$10="","",IF(COUNTIFS(LeaveName,'設定'!$B$10,LeaveType,"AL",LeaveDate,">="&I$13,LeaveDate,"<"&I$13+7)>0,"AL",IF(COUNTIFS(LeaveName,'設定'!$B$10,LeaveType,"SL",LeaveDate,">="&I$13,LeaveDate,"<"&I$13+7)>0,"SL",IF('設定'!$C$10="S","S",IF('設定'!$C$10="R",IF(MOD(INT((I$13-'設定'!$B$4)/7)+IF('設定'!$D$10="",0,'設定'!$D$10),16)<4,"A",IF(MOD(INT((I$13-'設定'!$B$4)/7)+IF('設定'!$D$10="",0,'設定'!$D$10),16)<8,"P",IF(MOD(INT((I$13-'設定'!$B$4)/7)+IF('設定'!$D$10="",0,'設定'!$D$10),16)<12,"N","P"))),"")))))) | J16: =IF(J$13="","",IF('設定'!$B$10="","",IF(COUNTIFS(LeaveName,'設定'!$B$10,LeaveType,"AL",LeaveDate,">="&J$13,LeaveDate,"<"&J$13+7)>0,"AL",IF(COUNTIFS(LeaveName,'設定'!$B$10,LeaveType,"SL",LeaveDate,">="&J$13,LeaveDate,"<"&J$13+7)>0,"SL",IF('設定'!$C$10="S","S",IF('設定'!$C$10="R",IF(MOD(INT((J$13-'設定'!$B$4)/7)+IF('設定'!$D$10="",0,'設定'!$D$10),16)<4,"A",IF(MOD(INT((J$13-'設定'!$B$4)/7)+IF('設定'!$D$10="",0,'設定'!$D$10),16)<8,"P",IF(MOD(INT((J$13-'設定'!$B$4)/7)+IF('設定'!$D$10="",0,'設定'!$D$10),16)<12,"N","P"))),"")))))) | K16: =IF(K$13="","",IF('設定'!$B$10="","",IF(COUNTIFS(LeaveName,'設定'!$B$10,LeaveType,"AL",LeaveDate,">="&K$13,LeaveDate,"<"&K$13+7)>0,"AL",IF(COUNTIFS(LeaveName,'設定'!$B$10,LeaveType,"SL",LeaveDate,">="&K$13,LeaveDate,"<"&K$13+7)>0,"SL",IF('設定'!$C$10="S","S",IF('設定'!$C$10="R",IF(MOD(INT((K$13-'設定'!$B$4)/7)+IF('設定'!$D$10="",0,'設定'!$D$10),16)<4,"A",IF(MOD(INT((K$13-'設定'!$B$4)/7)+IF('設定'!$D$10="",0,'設定'!$D$10),16)<8,"P",IF(MOD(INT((K$13-'設定'!$B$4)/7)+IF('設定'!$D$10="",0,'設定'!$D$10),16)<12,"N","P"))),"")))))) | L16: =IF(L$13="","",IF('設定'!$B$10="","",IF(COUNTIFS(LeaveName,'設定'!$B$10,LeaveType,"AL",LeaveDate,">="&L$13,LeaveDate,"<"&L$13+7)>0,"AL",IF(COUNTIFS(LeaveName,'設定'!$B$10,LeaveType,"SL",LeaveDate,">="&L$13,LeaveDate,"<"&L$13+7)>0,"SL",IF('設定'!$C$10="S","S",IF('設定'!$C$10="R",IF(MOD(INT((L$13-'設定'!$B$4)/7)+IF('設定'!$D$10="",0,'設定'!$D$10),16)<4,"A",IF(MOD(INT((L$13-'設定'!$B$4)/7)+IF('設定'!$D$10="",0,'設定'!$D$10),16)<8,"P",IF(MOD(INT((L$13-'設定'!$B$4)/7)+IF('設定'!$D$10="",0,'設定'!$D$10),16)<12,"N","P"))),"")))))) | M16: =IF(M$13="","",IF('設定'!$B$10="","",IF(COUNTIFS(LeaveName,'設定'!$B$10,LeaveType,"AL",LeaveDate,">="&M$13,LeaveDate,"<"&M$13+7)>0,"AL",IF(COUNTIFS(LeaveName,'設定'!$B$10,LeaveType,"SL",LeaveDate,">="&M$13,LeaveDate,"<"&M$13+7)>0,"SL",IF('設定'!$C$10="S","S",IF('設定'!$C$10="R",IF(MOD(INT((M$13-'設定'!$B$4)/7)+IF('設定'!$D$10="",0,'設定'!$D$10),16)<4,"A",IF(MOD(INT((M$13-'設定'!$B$4)/7)+IF('設定'!$D$10="",0,'設定'!$D$10),16)<8,"P",IF(MOD(INT((M$13-'設定'!$B$4)/7)+IF('設定'!$D$10="",0,'設定'!$D$10),16)<12,"N","P"))),"")))))) | N16: =IF(N$13="","",IF('設定'!$B$10="","",IF(COUNTIFS(LeaveName,'設定'!$B$10,LeaveType,"AL",LeaveDate,">="&N$13,LeaveDate,"<"&N$13+7)>0,"AL",IF(COUNTIFS(LeaveName,'設定'!$B$10,LeaveType,"SL",LeaveDate,">="&N$13,LeaveDate,"<"&N$13+7)>0,"SL",IF('設定'!$C$10="S","S",IF('設定'!$C$10="R",IF(MOD(INT((N$13-'設定'!$B$4)/7)+IF('設定'!$D$10="",0,'設定'!$D$10),16)<4,"A",IF(MOD(INT((N$13-'設定'!$B$4)/7)+IF('設定'!$D$10="",0,'設定'!$D$10),16)<8,"P",IF(MOD(INT((N$13-'設定'!$B$4)/7)+IF('設定'!$D$10="",0,'設定'!$D$10),16)<12,"N","P"))),"")))))) | ... BG16: =IF(BG$13="","",IF('設定'!$B$10="","",IF(COUNTIFS(LeaveName,'設定'!$B$10,LeaveType,"AL",LeaveDate,">="&BG$13,LeaveDate,"<"&BG$13+7)>0,"AL",IF(COUNTIFS(LeaveName,'設定'!$B$10,LeaveType,"SL",LeaveDate,">="&BG$13,LeaveDate,"<"&BG$13+7)>0,"SL",IF('設定'!$C$10="S","S",IF('設定'!$C$10="R",IF(MOD(INT((BG$13-'設定'!$B$4)/7)+IF('設定'!$D$10="",0,'設定'!$D$10),16)<4,"A",IF(MOD(INT((BG$13-'設定'!$B$4)/7)+IF('設定'!$D$10="",0,'設定'!$D$10),16)<8,"P",IF(MOD(INT((BG$13-'設定'!$B$4)/7)+IF('設定'!$D$10="",0,'設定'!$D$10),16)<12,"N","P"))),""))))))
A17: ='設定'!B11 | B17: =IF(A17="","",COUNTIFS(LeaveName,A17,LeaveType,"AL",LeaveDate,">="&DATE('設定'!$B$3,1,1),LeaveDate,"<="&DATE('設定'!$B$3,12,31))) | C17: =IF(A17="","",IF('設定'!E11="","",'設定'!E11-B17)) | D17: =IF(A17="","",E17+F17) | E17: 0 | F17: =IF(A17="","",CompYear4) | G17: =IF(G$13="","",IF('設定'!$B$11="","",IF(COUNTIFS(LeaveName,'設定'!$B$11,LeaveType,"AL",LeaveDate,">="&G$13,LeaveDate,"<"&G$13+7)>0,"AL",IF(COUNTIFS(LeaveName,'設定'!$B$11,LeaveType,"SL",LeaveDate,">="&G$13,LeaveDate,"<"&G$13+7)>0,"SL",IF('設定'!$C$11="S","S",IF('設定'!$C$11="R",IF(MOD(INT((G$13-'設定'!$B$4)/7)+IF('設定'!$D$11="",0,'設定'!$D$11),16)<4,"A",IF(MOD(INT((G$13-'設定'!$B$4)/7)+IF('設定'!$D$11="",0,'設定'!$D$11),16)<8,"P",IF(MOD(INT((G$13-'設定'!$B$4)/7)+IF('設定'!$D$11="",0,'設定'!$D$11),16)<12,"N","P"))),"")))))) | H17: =IF(H$13="","",IF('設定'!$B$11="","",IF(COUNTIFS(LeaveName,'設定'!$B$11,LeaveType,"AL",LeaveDate,">="&H$13,LeaveDate,"<"&H$13+7)>0,"AL",IF(COUNTIFS(LeaveName,'設定'!$B$11,LeaveType,"SL",LeaveDate,">="&H$13,LeaveDate,"<"&H$13+7)>0,"SL",IF('設定'!$C$11="S","S",IF('設定'!$C$11="R",IF(MOD(INT((H$13-'設定'!$B$4)/7)+IF('設定'!$D$11="",0,'設定'!$D$11),16)<4,"A",IF(MOD(INT((H$13-'設定'!$B$4)/7)+IF('設定'!$D$11="",0,'設定'!$D$11),16)<8,"P",IF(MOD(INT((H$13-'設定'!$B$4)/7)+IF('設定'!$D$11="",0,'設定'!$D$11),16)<12,"N","P"))),"")))))) | I17: =IF(I$13="","",IF('設定'!$B$11="","",IF(COUNTIFS(LeaveName,'設定'!$B$11,LeaveType,"AL",LeaveDate,">="&I$13,LeaveDate,"<"&I$13+7)>0,"AL",IF(COUNTIFS(LeaveName,'設定'!$B$11,LeaveType,"SL",LeaveDate,">="&I$13,LeaveDate,"<"&I$13+7)>0,"SL",IF('設定'!$C$11="S","S",IF('設定'!$C$11="R",IF(MOD(INT((I$13-'設定'!$B$4)/7)+IF('設定'!$D$11="",0,'設定'!$D$11),16)<4,"A",IF(MOD(INT((I$13-'設定'!$B$4)/7)+IF('設定'!$D$11="",0,'設定'!$D$11),16)<8,"P",IF(MOD(INT((I$13-'設定'!$B$4)/7)+IF('設定'!$D$11="",0,'設定'!$D$11),16)<12,"N","P"))),"")))))) | J17: =IF(J$13="","",IF('設定'!$B$11="","",IF(COUNTIFS(LeaveName,'設定'!$B$11,LeaveType,"AL",LeaveDate,">="&J$13,LeaveDate,"<"&J$13+7)>0,"AL",IF(COUNTIFS(LeaveName,'設定'!$B$11,LeaveType,"SL",LeaveDate,">="&J$13,LeaveDate,"<"&J$13+7)>0,"SL",IF('設定'!$C$11="S","S",IF('設定'!$C$11="R",IF(MOD(INT((J$13-'設定'!$B$4)/7)+IF('設定'!$D$11="",0,'設定'!$D$11),16)<4,"A",IF(MOD(INT((J$13-'設定'!$B$4)/7)+IF('設定'!$D$11="",0,'設定'!$D$11),16)<8,"P",IF(MOD(INT((J$13-'設定'!$B$4)/7)+IF('設定'!$D$11="",0,'設定'!$D$11),16)<12,"N","P"))),"")))))) | K17: =IF(K$13="","",IF('設定'!$B$11="","",IF(COUNTIFS(LeaveName,'設定'!$B$11,LeaveType,"AL",LeaveDate,">="&K$13,LeaveDate,"<"&K$13+7)>0,"AL",IF(COUNTIFS(LeaveName,'設定'!$B$11,LeaveType,"SL",LeaveDate,">="&K$13,LeaveDate,"<"&K$13+7)>0,"SL",IF('設定'!$C$11="S","S",IF('設定'!$C$11="R",IF(MOD(INT((K$13-'設定'!$B$4)/7)+IF('設定'!$D$11="",0,'設定'!$D$11),16)<4,"A",IF(MOD(INT((K$13-'設定'!$B$4)/7)+IF('設定'!$D$11="",0,'設定'!$D$11),16)<8,"P",IF(MOD(INT((K$13-'設定'!$B$4)/7)+IF('設定'!$D$11="",0,'設定'!$D$11),16)<12,"N","P"))),"")))))) | L17: =IF(L$13="","",IF('設定'!$B$11="","",IF(COUNTIFS(LeaveName,'設定'!$B$11,LeaveType,"AL",LeaveDate,">="&L$13,LeaveDate,"<"&L$13+7)>0,"AL",IF(COUNTIFS(LeaveName,'設定'!$B$11,LeaveType,"SL",LeaveDate,">="&L$13,LeaveDate,"<"&L$13+7)>0,"SL",IF('設定'!$C$11="S","S",IF('設定'!$C$11="R",IF(MOD(INT((L$13-'設定'!$B$4)/7)+IF('設定'!$D$11="",0,'設定'!$D$11),16)<4,"A",IF(MOD(INT((L$13-'設定'!$B$4)/7)+IF('設定'!$D$11="",0,'設定'!$D$11),16)<8,"P",IF(MOD(INT((L$13-'設定'!$B$4)/7)+IF('設定'!$D$11="",0,'設定'!$D$11),16)<12,"N","P"))),"")))))) | M17: =IF(M$13="","",IF('設定'!$B$11="","",IF(COUNTIFS(LeaveName,'設定'!$B$11,LeaveType,"AL",LeaveDate,">="&M$13,LeaveDate,"<"&M$13+7)>0,"AL",IF(COUNTIFS(LeaveName,'設定'!$B$11,LeaveType,"SL",LeaveDate,">="&M$13,LeaveDate,"<"&M$13+7)>0,"SL",IF('設定'!$C$11="S","S",IF('設定'!$C$11="R",IF(MOD(INT((M$13-'設定'!$B$4)/7)+IF('設定'!$D$11="",0,'設定'!$D$11),16)<4,"A",IF(MOD(INT((M$13-'設定'!$B$4)/7)+IF('設定'!$D$11="",0,'設定'!$D$11),16)<8,"P",IF(MOD(INT((M$13-'設定'!$B$4)/7)+IF('設定'!$D$11="",0,'設定'!$D$11),16)<12,"N","P"))),"")))))) | N17: =IF(N$13="","",IF('設定'!$B$11="","",IF(COUNTIFS(LeaveName,'設定'!$B$11,LeaveType,"AL",LeaveDate,">="&N$13,LeaveDate,"<"&N$13+7)>0,"AL",IF(COUNTIFS(LeaveName,'設定'!$B$11,LeaveType,"SL",LeaveDate,">="&N$13,LeaveDate,"<"&N$13+7)>0,"SL",IF('設定'!$C$11="S","S",IF('設定'!$C$11="R",IF(MOD(INT((N$13-'設定'!$B$4)/7)+IF('設定'!$D$11="",0,'設定'!$D$11),16)<4,"A",IF(MOD(INT((N$13-'設定'!$B$4)/7)+IF('設定'!$D$11="",0,'設定'!$D$11),16)<8,"P",IF(MOD(INT((N$13-'設定'!$B$4)/7)+IF('設定'!$D$11="",0,'設定'!$D$11),16)<12,"N","P"))),"")))))) | ... BG17: =IF(BG$13="","",IF('設定'!$B$11="","",IF(COUNTIFS(LeaveName,'設定'!$B$11,LeaveType,"AL",LeaveDate,">="&BG$13,LeaveDate,"<"&BG$13+7)>0,"AL",IF(COUNTIFS(LeaveName,'設定'!$B$11,LeaveType,"SL",LeaveDate,">="&BG$13,LeaveDate,"<"&BG$13+7)>0,"SL",IF('設定'!$C$11="S","S",IF('設定'!$C$11="R",IF(MOD(INT((BG$13-'設定'!$B$4)/7)+IF('設定'!$D$11="",0,'設定'!$D$11),16)<4,"A",IF(MOD(INT((BG$13-'設定'!$B$4)/7)+IF('設定'!$D$11="",0,'設定'!$D$11),16)<8,"P",IF(MOD(INT((BG$13-'設定'!$B$4)/7)+IF('設定'!$D$11="",0,'設定'!$D$11),16)<12,"N","P"))),""))))))
A18: ='設定'!B12 | B18: =IF(A18="","",COUNTIFS(LeaveName,A18,LeaveType,"AL",LeaveDate,">="&DATE('設定'!$B$3,1,1),LeaveDate,"<="&DATE('設定'!$B$3,12,31))) | C18: =IF(A18="","",IF('設定'!E12="","",'設定'!E12-B18)) | D18: =IF(A18="","",E18+F18) | E18: 0 | F18: =IF(A18="","",CompYear5) | G18: =IF(G$13="","",IF('設定'!$B$12="","",IF(COUNTIFS(LeaveName,'設定'!$B$12,LeaveType,"AL",LeaveDate,">="&G$13,LeaveDate,"<"&G$13+7)>0,"AL",IF(COUNTIFS(LeaveName,'設定'!$B$12,LeaveType,"SL",LeaveDate,">="&G$13,LeaveDate,"<"&G$13+7)>0,"SL",IF('設定'!$C$12="S","S",IF('設定'!$C$12="R",IF(MOD(INT((G$13-'設定'!$B$4)/7)+IF('設定'!$D$12="",0,'設定'!$D$12),16)<4,"A",IF(MOD(INT((G$13-'設定'!$B$4)/7)+IF('設定'!$D$12="",0,'設定'!$D$12),16)<8,"P",IF(MOD(INT((G$13-'設定'!$B$4)/7)+IF('設定'!$D$12="",0,'設定'!$D$12),16)<12,"N","P"))),"")))))) | H18: =IF(H$13="","",IF('設定'!$B$12="","",IF(COUNTIFS(LeaveName,'設定'!$B$12,LeaveType,"AL",LeaveDate,">="&H$13,LeaveDate,"<"&H$13+7)>0,"AL",IF(COUNTIFS(LeaveName,'設定'!$B$12,LeaveType,"SL",LeaveDate,">="&H$13,LeaveDate,"<"&H$13+7)>0,"SL",IF('設定'!$C$12="S","S",IF('設定'!$C$12="R",IF(MOD(INT((H$13-'設定'!$B$4)/7)+IF('設定'!$D$12="",0,'設定'!$D$12),16)<4,"A",IF(MOD(INT((H$13-'設定'!$B$4)/7)+IF('設定'!$D$12="",0,'設定'!$D$12),16)<8,"P",IF(MOD(INT((H$13-'設定'!$B$4)/7)+IF('設定'!$D$12="",0,'設定'!$D$12),16)<12,"N","P"))),"")))))) | I18: =IF(I$13="","",IF('設定'!$B$12="","",IF(COUNTIFS(LeaveName,'設定'!$B$12,LeaveType,"AL",LeaveDate,">="&I$13,LeaveDate,"<"&I$13+7)>0,"AL",IF(COUNTIFS(LeaveName,'設定'!$B$12,LeaveType,"SL",LeaveDate,">="&I$13,LeaveDate,"<"&I$13+7)>0,"SL",IF('設定'!$C$12="S","S",IF('設定'!$C$12="R",IF(MOD(INT((I$13-'設定'!$B$4)/7)+IF('設定'!$D$12="",0,'設定'!$D$12),16)<4,"A",IF(MOD(INT((I$13-'設定'!$B$4)/7)+IF('設定'!$D$12="",0,'設定'!$D$12),16)<8,"P",IF(MOD(INT((I$13-'設定'!$B$4)/7)+IF('設定'!$D$12="",0,'設定'!$D$12),16)<12,"N","P"))),"")))))) | J18: =IF(J$13="","",IF('設定'!$B$12="","",IF(COUNTIFS(LeaveName,'設定'!$B$12,LeaveType,"AL",LeaveDate,">="&J$13,LeaveDate,"<"&J$13+7)>0,"AL",IF(COUNTIFS(LeaveName,'設定'!$B$12,LeaveType,"SL",LeaveDate,">="&J$13,LeaveDate,"<"&J$13+7)>0,"SL",IF('設定'!$C$12="S","S",IF('設定'!$C$12="R",IF(MOD(INT((J$13-'設定'!$B$4)/7)+IF('設定'!$D$12="",0,'設定'!$D$12),16)<4,"A",IF(MOD(INT((J$13-'設定'!$B$4)/7)+IF('設定'!$D$12="",0,'設定'!$D$12),16)<8,"P",IF(MOD(INT((J$13-'設定'!$B$4)/7)+IF('設定'!$D$12="",0,'設定'!$D$12),16)<12,"N","P"))),"")))))) | K18: =IF(K$13="","",IF('設定'!$B$12="","",IF(COUNTIFS(LeaveName,'設定'!$B$12,LeaveType,"AL",LeaveDate,">="&K$13,LeaveDate,"<"&K$13+7)>0,"AL",IF(COUNTIFS(LeaveName,'設定'!$B$12,LeaveType,"SL",LeaveDate,">="&K$13,LeaveDate,"<"&K$13+7)>0,"SL",IF('設定'!$C$12="S","S",IF('設定'!$C$12="R",IF(MOD(INT((K$13-'設定'!$B$4)/7)+IF('設定'!$D$12="",0,'設定'!$D$12),16)<4,"A",IF(MOD(INT((K$13-'設定'!$B$4)/7)+IF('設定'!$D$12="",0,'設定'!$D$12),16)<8,"P",IF(MOD(INT((K$13-'設定'!$B$4)/7)+IF('設定'!$D$12="",0,'設定'!$D$12),16)<12,"N","P"))),"")))))) | L18: =IF(L$13="","",IF('設定'!$B$12="","",IF(COUNTIFS(LeaveName,'設定'!$B$12,LeaveType,"AL",LeaveDate,">="&L$13,LeaveDate,"<"&L$13+7)>0,"AL",IF(COUNTIFS(LeaveName,'設定'!$B$12,LeaveType,"SL",LeaveDate,">="&L$13,LeaveDate,"<"&L$13+7)>0,"SL",IF('設定'!$C$12="S","S",IF('設定'!$C$12="R",IF(MOD(INT((L$13-'設定'!$B$4)/7)+IF('設定'!$D$12="",0,'設定'!$D$12),16)<4,"A",IF(MOD(INT((L$13-'設定'!$B$4)/7)+IF('設定'!$D$12="",0,'設定'!$D$12),16)<8,"P",IF(MOD(INT((L$13-'設定'!$B$4)/7)+IF('設定'!$D$12="",0,'設定'!$D$12),16)<12,"N","P"))),"")))))) | M18: =IF(M$13="","",IF('設定'!$B$12="","",IF(COUNTIFS(LeaveName,'設定'!$B$12,LeaveType,"AL",LeaveDate,">="&M$13,LeaveDate,"<"&M$13+7)>0,"AL",IF(COUNTIFS(LeaveName,'設定'!$B$12,LeaveType,"SL",LeaveDate,">="&M$13,LeaveDate,"<"&M$13+7)>0,"SL",IF('設定'!$C$12="S","S",IF('設定'!$C$12="R",IF(MOD(INT((M$13-'設定'!$B$4)/7)+IF('設定'!$D$12="",0,'設定'!$D$12),16)<4,"A",IF(MOD(INT((M$13-'設定'!$B$4)/7)+IF('設定'!$D$12="",0,'設定'!$D$12),16)<8,"P",IF(MOD(INT((M$13-'設定'!$B$4)/7)+IF('設定'!$D$12="",0,'設定'!$D$12),16)<12,"N","P"))),"")))))) | N18: =IF(N$13="","",IF('設定'!$B$12="","",IF(COUNTIFS(LeaveName,'設定'!$B$12,LeaveType,"AL",LeaveDate,">="&N$13,LeaveDate,"<"&N$13+7)>0,"AL",IF(COUNTIFS(LeaveName,'設定'!$B$12,LeaveType,"SL",LeaveDate,">="&N$13,LeaveDate,"<"&N$13+7)>0,"SL",IF('設定'!$C$12="S","S",IF('設定'!$C$12="R",IF(MOD(INT((N$13-'設定'!$B$4)/7)+IF('設定'!$D$12="",0,'設定'!$D$12),16)<4,"A",IF(MOD(INT((N$13-'設定'!$B$4)/7)+IF('設定'!$D$12="",0,'設定'!$D$12),16)<8,"P",IF(MOD(INT((N$13-'設定'!$B$4)/7)+IF('設定'!$D$12="",0,'設定'!$D$12),16)<12,"N","P"))),"")))))) | ... BG18: =IF(BG$13="","",IF('設定'!$B$12="","",IF(COUNTIFS(LeaveName,'設定'!$B$12,LeaveType,"AL",LeaveDate,">="&BG$13,LeaveDate,"<"&BG$13+7)>0,"AL",IF(COUNTIFS(LeaveName,'設定'!$B$12,LeaveType,"SL",LeaveDate,">="&BG$13,LeaveDate,"<"&BG$13+7)>0,"SL",IF('設定'!$C$12="S","S",IF('設定'!$C$12="R",IF(MOD(INT((BG$13-'設定'!$B$4)/7)+IF('設定'!$D$12="",0,'設定'!$D$12),16)<4,"A",IF(MOD(INT((BG$13-'設定'!$B$4)/7)+IF('設定'!$D$12="",0,'設定'!$D$12),16)<8,"P",IF(MOD(INT((BG$13-'設定'!$B$4)/7)+IF('設定'!$D$12="",0,'設定'!$D$12),16)<12,"N","P"))),""))))))
A19: ='設定'!B13 | B19: =IF(A19="","",COUNTIFS(LeaveName,A19,LeaveType,"AL",LeaveDate,">="&DATE('設定'!$B$3,1,1),LeaveDate,"<="&DATE('設定'!$B$3,12,31))) | C19: =IF(A19="","",IF('設定'!E13="","",'設定'!E13-B19)) | D19: =IF(A19="","",E19+F19) | F19: =IF(A19="","",CompYear6) | G19: =IF(G$13="","",IF('設定'!$B$13="","",IF(COUNTIFS(LeaveName,'設定'!$B$13,LeaveType,"AL",LeaveDate,">="&G$13,LeaveDate,"<"&G$13+7)>0,"AL",IF(COUNTIFS(LeaveName,'設定'!$B$13,LeaveType,"SL",LeaveDate,">="&G$13,LeaveDate,"<"&G$13+7)>0,"SL",IF('設定'!$C$13="S","S",IF('設定'!$C$13="R",IF(MOD(INT((G$13-'設定'!$B$4)/7)+IF('設定'!$D$13="",0,'設定'!$D$13),16)<4,"A",IF(MOD(INT((G$13-'設定'!$B$4)/7)+IF('設定'!$D$13="",0,'設定'!$D$13),16)<8,"P",IF(MOD(INT((G$13-'設定'!$B$4)/7)+IF('設定'!$D$13="",0,'設定'!$D$13),16)<12,"N","P"))),"")))))) | H19: =IF(H$13="","",IF('設定'!$B$13="","",IF(COUNTIFS(LeaveName,'設定'!$B$13,LeaveType,"AL",LeaveDate,">="&H$13,LeaveDate,"<"&H$13+7)>0,"AL",IF(COUNTIFS(LeaveName,'設定'!$B$13,LeaveType,"SL",LeaveDate,">="&H$13,LeaveDate,"<"&H$13+7)>0,"SL",IF('設定'!$C$13="S","S",IF('設定'!$C$13="R",IF(MOD(INT((H$13-'設定'!$B$4)/7)+IF('設定'!$D$13="",0,'設定'!$D$13),16)<4,"A",IF(MOD(INT((H$13-'設定'!$B$4)/7)+IF('設定'!$D$13="",0,'設定'!$D$13),16)<8,"P",IF(MOD(INT((H$13-'設定'!$B$4)/7)+IF('設定'!$D$13="",0,'設定'!$D$13),16)<12,"N","P"))),"")))))) | I19: =IF(I$13="","",IF('設定'!$B$13="","",IF(COUNTIFS(LeaveName,'設定'!$B$13,LeaveType,"AL",LeaveDate,">="&I$13,LeaveDate,"<"&I$13+7)>0,"AL",IF(COUNTIFS(LeaveName,'設定'!$B$13,LeaveType,"SL",LeaveDate,">="&I$13,LeaveDate,"<"&I$13+7)>0,"SL",IF('設定'!$C$13="S","S",IF('設定'!$C$13="R",IF(MOD(INT((I$13-'設定'!$B$4)/7)+IF('設定'!$D$13="",0,'設定'!$D$13),16)<4,"A",IF(MOD(INT((I$13-'設定'!$B$4)/7)+IF('設定'!$D$13="",0,'設定'!$D$13),16)<8,"P",IF(MOD(INT((I$13-'設定'!$B$4)/7)+IF('設定'!$D$13="",0,'設定'!$D$13),16)<12,"N","P"))),"")))))) | J19: =IF(J$13="","",IF('設定'!$B$13="","",IF(COUNTIFS(LeaveName,'設定'!$B$13,LeaveType,"AL",LeaveDate,">="&J$13,LeaveDate,"<"&J$13+7)>0,"AL",IF(COUNTIFS(LeaveName,'設定'!$B$13,LeaveType,"SL",LeaveDate,">="&J$13,LeaveDate,"<"&J$13+7)>0,"SL",IF('設定'!$C$13="S","S",IF('設定'!$C$13="R",IF(MOD(INT((J$13-'設定'!$B$4)/7)+IF('設定'!$D$13="",0,'設定'!$D$13),16)<4,"A",IF(MOD(INT((J$13-'設定'!$B$4)/7)+IF('設定'!$D$13="",0,'設定'!$D$13),16)<8,"P",IF(MOD(INT((J$13-'設定'!$B$4)/7)+IF('設定'!$D$13="",0,'設定'!$D$13),16)<12,"N","P"))),"")))))) | K19: =IF(K$13="","",IF('設定'!$B$13="","",IF(COUNTIFS(LeaveName,'設定'!$B$13,LeaveType,"AL",LeaveDate,">="&K$13,LeaveDate,"<"&K$13+7)>0,"AL",IF(COUNTIFS(LeaveName,'設定'!$B$13,LeaveType,"SL",LeaveDate,">="&K$13,LeaveDate,"<"&K$13+7)>0,"SL",IF('設定'!$C$13="S","S",IF('設定'!$C$13="R",IF(MOD(INT((K$13-'設定'!$B$4)/7)+IF('設定'!$D$13="",0,'設定'!$D$13),16)<4,"A",IF(MOD(INT((K$13-'設定'!$B$4)/7)+IF('設定'!$D$13="",0,'設定'!$D$13),16)<8,"P",IF(MOD(INT((K$13-'設定'!$B$4)/7)+IF('設定'!$D$13="",0,'設定'!$D$13),16)<12,"N","P"))),"")))))) | L19: =IF(L$13="","",IF('設定'!$B$13="","",IF(COUNTIFS(LeaveName,'設定'!$B$13,LeaveType,"AL",LeaveDate,">="&L$13,LeaveDate,"<"&L$13+7)>0,"AL",IF(COUNTIFS(LeaveName,'設定'!$B$13,LeaveType,"SL",LeaveDate,">="&L$13,LeaveDate,"<"&L$13+7)>0,"SL",IF('設定'!$C$13="S","S",IF('設定'!$C$13="R",IF(MOD(INT((L$13-'設定'!$B$4)/7)+IF('設定'!$D$13="",0,'設定'!$D$13),16)<4,"A",IF(MOD(INT((L$13-'設定'!$B$4)/7)+IF('設定'!$D$13="",0,'設定'!$D$13),16)<8,"P",IF(MOD(INT((L$13-'設定'!$B$4)/7)+IF('設定'!$D$13="",0,'設定'!$D$13),16)<12,"N","P"))),"")))))) | M19: =IF(M$13="","",IF('設定'!$B$13="","",IF(COUNTIFS(LeaveName,'設定'!$B$13,LeaveType,"AL",LeaveDate,">="&M$13,LeaveDate,"<"&M$13+7)>0,"AL",IF(COUNTIFS(LeaveName,'設定'!$B$13,LeaveType,"SL",LeaveDate,">="&M$13,LeaveDate,"<"&M$13+7)>0,"SL",IF('設定'!$C$13="S","S",IF('設定'!$C$13="R",IF(MOD(INT((M$13-'設定'!$B$4)/7)+IF('設定'!$D$13="",0,'設定'!$D$13),16)<4,"A",IF(MOD(INT((M$13-'設定'!$B$4)/7)+IF('設定'!$D$13="",0,'設定'!$D$13),16)<8,"P",IF(MOD(INT((M$13-'設定'!$B$4)/7)+IF('設定'!$D$13="",0,'設定'!$D$13),16)<12,"N","P"))),"")))))) | N19: =IF(N$13="","",IF('設定'!$B$13="","",IF(COUNTIFS(LeaveName,'設定'!$B$13,LeaveType,"AL",LeaveDate,">="&N$13,LeaveDate,"<"&N$13+7)>0,"AL",IF(COUNTIFS(LeaveName,'設定'!$B$13,LeaveType,"SL",LeaveDate,">="&N$13,LeaveDate,"<"&N$13+7)>0,"SL",IF('設定'!$C$13="S","S",IF('設定'!$C$13="R",IF(MOD(INT((N$13-'設定'!$B$4)/7)+IF('設定'!$D$13="",0,'設定'!$D$13),16)<4,"A",IF(MOD(INT((N$13-'設定'!$B$4)/7)+IF('設定'!$D$13="",0,'設定'!$D$13),16)<8,"P",IF(MOD(INT((N$13-'設定'!$B$4)/7)+IF('設定'!$D$13="",0,'設定'!$D$13),16)<12,"N","P"))),"")))))) | ... BG19: =IF(BG$13="","",IF('設定'!$B$13="","",IF(COUNTIFS(LeaveName,'設定'!$B$13,LeaveType,"AL",LeaveDate,">="&BG$13,LeaveDate,"<"&BG$13+7)>0,"AL",IF(COUNTIFS(LeaveName,'設定'!$B$13,LeaveType,"SL",LeaveDate,">="&BG$13,LeaveDate,"<"&BG$13+7)>0,"SL",IF('設定'!$C$13="S","S",IF('設定'!$C$13="R",IF(MOD(INT((BG$13-'設定'!$B$4)/7)+IF('設定'!$D$13="",0,'設定'!$D$13),16)<4,"A",IF(MOD(INT((BG$13-'設定'!$B$4)/7)+IF('設定'!$D$13="",0,'設定'!$D$13),16)<8,"P",IF(MOD(INT((BG$13-'設定'!$B$4)/7)+IF('設定'!$D$13="",0,'設定'!$D$13),16)<12,"N","P"))),""))))))
A20: 公眾假期 | G20: =IF(G$13="","",IF(COUNTIFS(HolidayDates,">="&G$13,HolidayDates,"<"&G$13+7,HolidayDates,"<>")=0,"","假"&COUNTIFS(HolidayDates,">="&G$13,HolidayDates,"<"&G$13+7,HolidayDates,"<>"))) | H20: =IF(H$13="","",IF(COUNTIFS(HolidayDates,">="&H$13,HolidayDates,"<"&H$13+7,HolidayDates,"<>")=0,"","假"&COUNTIFS(HolidayDates,">="&H$13,HolidayDates,"<"&H$13+7,HolidayDates,"<>"))) | I20: =IF(I$13="","",IF(COUNTIFS(HolidayDates,">="&I$13,HolidayDates,"<"&I$13+7,HolidayDates,"<>")=0,"","假"&COUNTIFS(HolidayDates,">="&I$13,HolidayDates,"<"&I$13+7,HolidayDates,"<>"))) | J20: =IF(J$13="","",IF(COUNTIFS(HolidayDates,">="&J$13,HolidayDates,"<"&J$13+7,HolidayDates,"<>")=0,"","假"&COUNTIFS(HolidayDates,">="&J$13,HolidayDates,"<"&J$13+7,HolidayDates,"<>"))) | K20: =IF(K$13="","",IF(COUNTIFS(HolidayDates,">="&K$13,HolidayDates,"<"&K$13+7,HolidayDates,"<>")=0,"","假"&COUNTIFS(HolidayDates,">="&K$13,HolidayDates,"<"&K$13+7,HolidayDates,"<>"))) | L20: =IF(L$13="","",IF(COUNTIFS(HolidayDates,">="&L$13,HolidayDates,"<"&L$13+7,HolidayDates,"<>")=0,"","假"&COUNTIFS(HolidayDates,">="&L$13,HolidayDates,"<"&L$13+7,HolidayDates,"<>"))) | M20: =IF(M$13="","",IF(COUNTIFS(HolidayDates,">="&M$13,HolidayDates,"<"&M$13+7,HolidayDates,"<>")=0,"","假"&COUNTIFS(HolidayDates,">="&M$13,HolidayDates,"<"&M$13+7,HolidayDates,"<>"))) | N20: =IF(N$13="","",IF(COUNTIFS(HolidayDates,">="&N$13,HolidayDates,"<"&N$13+7,HolidayDates,"<>")=0,"","假"&COUNTIFS(HolidayDates,">="&N$13,HolidayDates,"<"&N$13+7,HolidayDates,"<>"))) | ... BG20: =IF(BG$13="","",IF(COUNTIFS(HolidayDates,">="&BG$13,HolidayDates,"<"&BG$13+7,HolidayDates,"<>")=0,"","假"&COUNTIFS(HolidayDates,">="&BG$13,HolidayDates,"<"&BG$13+7,HolidayDates,"<>")))
A21: （系統） | G21: =IF(G$13="","",COUNTIFS(HolidayDates,">="&G$13,HolidayDates,"<"&G$13+7,HolidayDates,"<>")) | H21: =IF(H$13="","",COUNTIFS(HolidayDates,">="&H$13,HolidayDates,"<"&H$13+7,HolidayDates,"<>")) | I21: =IF(I$13="","",COUNTIFS(HolidayDates,">="&I$13,HolidayDates,"<"&I$13+7,HolidayDates,"<>")) | J21: =IF(J$13="","",COUNTIFS(HolidayDates,">="&J$13,HolidayDates,"<"&J$13+7,HolidayDates,"<>")) | K21: =IF(K$13="","",COUNTIFS(HolidayDates,">="&K$13,HolidayDates,"<"&K$13+7,HolidayDates,"<>")) | L21: =IF(L$13="","",COUNTIFS(HolidayDates,">="&L$13,HolidayDates,"<"&L$13+7,HolidayDates,"<>")) | M21: =IF(M$13="","",COUNTIFS(HolidayDates,">="&M$13,HolidayDates,"<"&M$13+7,HolidayDates,"<>")) | N21: =IF(N$13="","",COUNTIFS(HolidayDates,">="&N$13,HolidayDates,"<"&N$13+7,HolidayDates,"<>")) | ... BG21: =IF(BG$13="","",COUNTIFS(HolidayDates,">="&BG$13,HolidayDates,"<"&BG$13+7,HolidayDates,"<>"))
A23: 使用提示（詳見「使用提示」工作表）
A24: 1. 請假：只在「請假登記」新增列（姓名＋日期＋AL/SL）；主表與月曆會自動顯示。
A25: 2. 補假：在「假期上班登記」對應假期列用下拉選擇上班人員；主表補假欄自動更新。
A26: 3. 換年：改「設定」顯示年份，並在「公眾假期」追加假期；基準日 2026-06-29 勿改。
A27: 4. 年假額度：在「設定」每人「年假額度（天）」各自填寫；剩餘年假＝個人額度−已用（按請假登記天數）。
A28: 5. 同週若有超過 2 人出現 AL 或 SL（週欄顯示），整欄標紅警示。

Sheet 設定
A1: 部門更表 — 設定區
A3: 顯示年份 | B3: 2026 | C3: ← 每年年頭只改此數字，全年週份日期與班次自動重算
A4: 輪班基準日（永久固定） | B4: 46202 | C4: ← 永遠不要修改！所有輪班以此日為錨點跨年連續計算
A5: 說明 | B5: 16週循環：4週A → 4週P → 4週N → 4週P。Offset 錯開 0/4/8/12。年假額度改為每人獨立設定（見下表）。請假請只在「請假登記」輸入。
A7: 編號 | B7: 員工姓名 | C7: 班次類型 | D7: 初始Offset | E7: 年假額度（天） | F7: 說明
A8: 1 | B8: ARTHUR | C8: S | E8: 12 | F8: 固定 S 班，全年不變
A9: 2 | B9: PATRICK | C9: R | D9: 0 | E9: 12 | F9: 輪班 offset=0
A10: 3 | B10: CARREY | C10: R | D10: 4 | E10: 12 | F10: 輪班 offset=4
A11: 4 | B11: CESC | C11: R | D11: 8 | E11: 12 | F11: 輪班 offset=8
A12: 5 | B12: LUCAS | C12: R | D12: 12 | E12: 12 | F12: 輪班 offset=12
A13: 6 | C13: V | D13: 0 | F13: 填姓名後類型改 R/S，並設定 Offset 與年假額度
A15: 班次／假別顏色圖例（與排班表、月曆一致）
A16: S | B16: A | C16: P | D16: N | E16: AL | F16: SL
A17: 正常班 | B17: 早班 | C17: 中班 | D17: 晚班 | E17: 年假 | F17: 病假
A19: 輪班公式
A20: 週序=INT((該週一−基準日)/7)+Offset；MOD(週序,16)：0–3→A，4–7→P，8–11→N，12–15→P

Sheet 請假登記
A1: 請假登記（全年唯一請假輸入源）
A2: 每一行＝一位員工某一天的請假。連續多日請逐日新增多行。排班表／月曆的 AL・SL 顯示與年假統計皆從此表用公式查找，請勿在其他表輸入請假。
A4: 員工姓名 | B4: 請假日期 | C4: 假別 | E4: 提示
E5: 假別只能填 AL 或 SL；日期請填實際請假當天（非週一）。

Sheet 本月排班日曆
A1: 本月排班日曆（純檢視｜請勿在此輸入）
A2: 目前月份 | B2: =TEXT(TODAY(),"YYYY年M月") | C2: ← 隨 TODAY() 自動切換；請假異動請到「請假登記」
A3: 本月1日 | B3: =DATE(YEAR(TODAY()),MONTH(TODAY()),1) | C3: 月曆起始週一 | D3: =B3-WEEKDAY(B3,2)+1
A5: 星期一 | B5: 星期二 | C5: 星期三 | D5: 星期四 | E5: 星期五 | F5: 星期六 | G5: 星期日
A6: =IF(OR(MONTH($D$3+0*7+0)<>MONTH($B$3),YEAR($D$3+0*7+0)<>YEAR($B$3)),"",$D$3+0*7+0) | B6: =IF(OR(MONTH($D$3+0*7+1)<>MONTH($B$3),YEAR($D$3+0*7+1)<>YEAR($B$3)),"",$D$3+0*7+1) | C6: =IF(OR(MONTH($D$3+0*7+2)<>MONTH($B$3),YEAR($D$3+0*7+2)<>YEAR($B$3)),"",$D$3+0*7+2) | D6: =IF(OR(MONTH($D$3+0*7+3)<>MONTH($B$3),YEAR($D$3+0*7+3)<>YEAR($B$3)),"",$D$3+0*7+3) | E6: =IF(OR(MONTH($D$3+0*7+4)<>MONTH($B$3),YEAR($D$3+0*7+4)<>YEAR($B$3)),"",$D$3+0*7+4) | F6: =IF(OR(MONTH($D$3+0*7+5)<>MONTH($B$3),YEAR($D$3+0*7+5)<>YEAR($B$3)),"",$D$3+0*7+5) | G6: =IF(OR(MONTH($D$3+0*7+6)<>MONTH($B$3),YEAR($D$3+0*7+6)<>YEAR($B$3)),"",$D$3+0*7+6) | I6: 日期
A7: =IF(A6="","",IFERROR(INDEX(HolidayNames,MATCH($D$3+0*7+0,HolidayDates,0)),"")) | B7: =IF(B6="","",IFERROR(INDEX(HolidayNames,MATCH($D$3+0*7+1,HolidayDates,0)),"")) | C7: =IF(C6="","",IFERROR(INDEX(HolidayNames,MATCH($D$3+0*7+2,HolidayDates,0)),"")) | D7: =IF(D6="","",IFERROR(INDEX(HolidayNames,MATCH($D$3+0*7+3,HolidayDates,0)),"")) | E7: =IF(E6="","",IFERROR(INDEX(HolidayNames,MATCH($D$3+0*7+4,HolidayDates,0)),"")) | F7: =IF(F6="","",IFERROR(INDEX(HolidayNames,MATCH($D$3+0*7+5,HolidayDates,0)),"")) | G7: =IF(G6="","",IFERROR(INDEX(HolidayNames,MATCH($D$3+0*7+6,HolidayDates,0)),"")) | I7: 公眾假期
A8: =IF(OR(A6="",'設定'!$B$8=""),"",IF(COUNTIFS(LeaveName,'設定'!$B$8,LeaveDate,"="&($D$3+0*7+0),LeaveType,"AL")>0,"AL",IF(COUNTIFS(LeaveName,'設定'!$B$8,LeaveDate,"="&($D$3+0*7+0),LeaveType,"SL")>0,"SL",IF('設定'!$B$8="","",IF('設定'!$C$8="S","S",IF('設定'!$C$8="R",IF(MOD(INT((($D$3+0*7+0-WEEKDAY($D$3+0*7+0,2)+1)-'設定'!$B$4)/7)+IF('設定'!$D$8="",0,'設定'!$D$8),16)<4,"A",IF(MOD(INT((($D$3+0*7+0-WEEKDAY($D$3+0*7+0,2)+1)-'設定'!$B$4)/7)+IF('設定'!$D$8="",0,'設定'!$D$8),16)<8,"P",IF(MOD(INT((($D$3+0*7+0-WEEKDAY($D$3+0*7+0,2)+1)-'設定'!$B$4)/7)+IF('設定'!$D$8="",0,'設定'!$D$8),16)<12,"N","P"))),"")))))) | B8: =IF(OR(B6="",'設定'!$B$8=""),"",IF(COUNTIFS(LeaveName,'設定'!$B$8,LeaveDate,"="&($D$3+0*7+1),LeaveType,"AL")>0,"AL",IF(COUNTIFS(LeaveName,'設定'!$B$8,LeaveDate,"="&($D$3+0*7+1),LeaveType,"SL")>0,"SL",IF('設定'!$B$8="","",IF('設定'!$C$8="S","S",IF('設定'!$C$8="R",IF(MOD(INT((($D$3+0*7+1-WEEKDAY($D$3+0*7+1,2)+1)-'設定'!$B$4)/7)+IF('設定'!$D$8="",0,'設定'!$D$8),16)<4,"A",IF(MOD(INT((($D$3+0*7+1-WEEKDAY($D$3+0*7+1,2)+1)-'設定'!$B$4)/7)+IF('設定'!$D$8="",0,'設定'!$D$8),16)<8,"P",IF(MOD(INT((($D$3+0*7+1-WEEKDAY($D$3+0*7+1,2)+1)-'設定'!$B$4)/7)+IF('設定'!$D$8="",0,'設定'!$D$8),16)<12,"N","P"))),"")))))) | C8: =IF(OR(C6="",'設定'!$B$8=""),"",IF(COUNTIFS(LeaveName,'設定'!$B$8,LeaveDate,"="&($D$3+0*7+2),LeaveType,"AL")>0,"AL",IF(COUNTIFS(LeaveName,'設定'!$B$8,LeaveDate,"="&($D$3+0*7+2),LeaveType,"SL")>0,"SL",IF('設定'!$B$8="","",IF('設定'!$C$8="S","S",IF('設定'!$C$8="R",IF(MOD(INT((($D$3+0*7+2-WEEKDAY($D$3+0*7+2,2)+1)-'設定'!$B$4)/7)+IF('設定'!$D$8="",0,'設定'!$D$8),16)<4,"A",IF(MOD(INT((($D$3+0*7+2-WEEKDAY($D$3+0*7+2,2)+1)-'設定'!$B$4)/7)+IF('設定'!$D$8="",0,'設定'!$D$8),16)<8,"P",IF(MOD(INT((($D$3+0*7+2-WEEKDAY($D$3+0*7+2,2)+1)-'設定'!$B$4)/7)+IF('設定'!$D$8="",0,'設定'!$D$8),16)<12,"N","P"))),"")))))) | D8: =IF(OR(D6="",'設定'!$B$8=""),"",IF(COUNTIFS(LeaveName,'設定'!$B$8,LeaveDate,"="&($D$3+0*7+3),LeaveType,"AL")>0,"AL",IF(COUNTIFS(LeaveName,'設定'!$B$8,LeaveDate,"="&($D$3+0*7+3),LeaveType,"SL")>0,"SL",IF('設定'!$B$8="","",IF('設定'!$C$8="S","S",IF('設定'!$C$8="R",IF(MOD(INT((($D$3+0*7+3-WEEKDAY($D$3+0*7+3,2)+1)-'設定'!$B$4)/7)+IF('設定'!$D$8="",0,'設定'!$D$8),16)<4,"A",IF(MOD(INT((($D$3+0*7+3-WEEKDAY($D$3+0*7+3,2)+1)-'設定'!$B$4)/7)+IF('設定'!$D$8="",0,'設定'!$D$8),16)<8,"P",IF(MOD(INT((($D$3+0*7+3-WEEKDAY($D$3+0*7+3,2)+1)-'設定'!$B$4)/7)+IF('設定'!$D$8="",0,'設定'!$D$8),16)<12,"N","P"))),"")))))) | E8: =IF(OR(E6="",'設定'!$B$8=""),"",IF(COUNTIFS(LeaveName,'設定'!$B$8,LeaveDate,"="&($D$3+0*7+4),LeaveType,"AL")>0,"AL",IF(COUNTIFS(LeaveName,'設定'!$B$8,LeaveDate,"="&($D$3+0*7+4),LeaveType,"SL")>0,"SL",IF('設定'!$B$8="","",IF('設定'!$C$8="S","S",IF('設定'!$C$8="R",IF(MOD(INT((($D$3+0*7+4-WEEKDAY($D$3+0*7+4,2)+1)-'設定'!$B$4)/7)+IF('設定'!$D$8="",0,'設定'!$D$8),16)<4,"A",IF(MOD(INT((($D$3+0*7+4-WEEKDAY($D$3+0*7+4,2)+1)-'設定'!$B$4)/7)+IF('設定'!$D$8="",0,'設定'!$D$8),16)<8,"P",IF(MOD(INT((($D$3+0*7+4-WEEKDAY($D$3+0*7+4,2)+1)-'設定'!$B$4)/7)+IF('設定'!$D$8="",0,'設定'!$D$8),16)<12,"N","P"))),"")))))) | F8: =IF(OR(F6="",'設定'!$B$8=""),"",IF(COUNTIFS(LeaveName,'設定'!$B$8,LeaveDate,"="&($D$3+0*7+5),LeaveType,"AL")>0,"AL",IF(COUNTIFS(LeaveName,'設定'!$B$8,LeaveDate,"="&($D$3+0*7+5),LeaveType,"SL")>0,"SL",IF('設定'!$B$8="","",IF('設定'!$C$8="S","S",IF('設定'!$C$8="R",IF(MOD(INT((($D$3+0*7+5-WEEKDAY($D$3+0*7+5,2)+1)-'設定'!$B$4)/7)+IF('設定'!$D$8="",0,'設定'!$D$8),16)<4,"A",IF(MOD(INT((($D$3+0*7+5-WEEKDAY($D$3+0*7+5,2)+1)-'設定'!$B$4)/7)+IF('設定'!$D$8="",0,'設定'!$D$8),16)<8,"P",IF(MOD(INT((($D$3+0*7+5-WEEKDAY($D$3+0*7+5,2)+1)-'設定'!$B$4)/7)+IF('設定'!$D$8="",0,'設定'!$D$8),16)<12,"N","P"))),"")))))) | G8: =IF(OR(G6="",'設定'!$B$8=""),"",IF(COUNTIFS(LeaveName,'設定'!$B$8,LeaveDate,"="&($D$3+0*7+6),LeaveType,"AL")>0,"AL",IF(COUNTIFS(LeaveName,'設定'!$B$8,LeaveDate,"="&($D$3+0*7+6),LeaveType,"SL")>0,"SL",IF('設定'!$B$8="","",IF('設定'!$C$8="S","S",IF('設定'!$C$8="R",IF(MOD(INT((($D$3+0*7+6-WEEKDAY($D$3+0*7+6,2)+1)-'設定'!$B$4)/7)+IF('設定'!$D$8="",0,'設定'!$D$8),16)<4,"A",IF(MOD(INT((($D$3+0*7+6-WEEKDAY($D$3+0*7+6,2)+1)-'設定'!$B$4)/7)+IF('設定'!$D$8="",0,'設定'!$D$8),16)<8,"P",IF(MOD(INT((($D$3+0*7+6-WEEKDAY($D$3+0*7+6,2)+1)-'設定'!$B$4)/7)+IF('設定'!$D$8="",0,'設定'!$D$8),16)<12,"N","P"))),"")))))) | I8: ='設定'!B8
A9: =IF(OR(A6="",'設定'!$B$9=""),"",IF(COUNTIFS(LeaveName,'設定'!$B$9,LeaveDate,"="&($D$3+0*7+0),LeaveType,"AL")>0,"AL",IF(COUNTIFS(LeaveName,'設定'!$B$9,LeaveDate,"="&($D$3+0*7+0),LeaveType,"SL")>0,"SL",IF('設定'!$B$9="","",IF('設定'!$C$9="S","S",IF('設定'!$C$9="R",IF(MOD(INT((($D$3+0*7+0-WEEKDAY($D$3+0*7+0,2)+1)-'設定'!$B$4)/7)+IF('設定'!$D$9="",0,'設定'!$D$9),16)<4,"A",IF(MOD(INT((($D$3+0*7+0-WEEKDAY($D$3+0*7+0,2)+1)-'設定'!$B$4)/7)+IF('設定'!$D$9="",0,'設定'!$D$9),16)<8,"P",IF(MOD(INT((($D$3+0*7+0-WEEKDAY($D$3+0*7+0,2)+1)-'設定'!$B$4)/7)+IF('設定'!$D$9="",0,'設定'!$D$9),16)<12,"N","P"))),"")))))) | B9: =IF(OR(B6="",'設定'!$B$9=""),"",IF(COUNTIFS(LeaveName,'設定'!$B$9,LeaveDate,"="&($D$3+0*7+1),LeaveType,"AL")>0,"AL",IF(COUNTIFS(LeaveName,'設定'!$B$9,LeaveDate,"="&($D$3+0*7+1),LeaveType,"SL")>0,"SL",IF('設定'!$B$9="","",IF('設定'!$C$9="S","S",IF('設定'!$C$9="R",IF(MOD(INT((($D$3+0*7+1-WEEKDAY($D$3+0*7+1,2)+1)-'設定'!$B$4)/7)+IF('設定'!$D$9="",0,'設定'!$D$9),16)<4,"A",IF(MOD(INT((($D$3+0*7+1-WEEKDAY($D$3+0*7+1,2)+1)-'設定'!$B$4)/7)+IF('設定'!$D$9="",0,'設定'!$D$9),16)<8,"P",IF(MOD(INT((($D$3+0*7+1-WEEKDAY($D$3+0*7+1,2)+1)-'設定'!$B$4)/7)+IF('設定'!$D$9="",0,'設定'!$D$9),16)<12,"N","P"))),"")))))) | C9: =IF(OR(C6="",'設定'!$B$9=""),"",IF(COUNTIFS(LeaveName,'設定'!$B$9,LeaveDate,"="&($D$3+0*7+2),LeaveType,"AL")>0,"AL",IF(COUNTIFS(LeaveName,'設定'!$B$9,LeaveDate,"="&($D$3+0*7+2),LeaveType,"SL")>0,"SL",IF('設定'!$B$9="","",IF('設定'!$C$9="S","S",IF('設定'!$C$9="R",IF(MOD(INT((($D$3+0*7+2-WEEKDAY($D$3+0*7+2,2)+1)-'設定'!$B$4)/7)+IF('設定'!$D$9="",0,'設定'!$D$9),16)<4,"A",IF(MOD(INT((($D$3+0*7+2-WEEKDAY($D$3+0*7+2,2)+1)-'設定'!$B$4)/7)+IF('設定'!$D$9="",0,'設定'!$D$9),16)<8,"P",IF(MOD(INT((($D$3+0*7+2-WEEKDAY($D$3+0*7+2,2)+1)-'設定'!$B$4)/7)+IF('設定'!$D$9="",0,'設定'!$D$9),16)<12,"N","P"))),"")))))) | D9: =IF(OR(D6="",'設定'!$B$9=""),"",IF(COUNTIFS(LeaveName,'設定'!$B$9,LeaveDate,"="&($D$3+0*7+3),LeaveType,"AL")>0,"AL",IF(COUNTIFS(LeaveName,'設定'!$B$9,LeaveDate,"="&($D$3+0*7+3),LeaveType,"SL")>0,"SL",IF('設定'!$B$9="","",IF('設定'!$C$9="S","S",IF('設定'!$C$9="R",IF(MOD(INT((($D$3+0*7+3-WEEKDAY($D$3+0*7+3,2)+1)-'設定'!$B$4)/7)+IF('設定'!$D$9="",0,'設定'!$D$9),16)<4,"A",IF(MOD(INT((($D$3+0*7+3-WEEKDAY($D$3+0*7+3,2)+1)-'設定'!$B$4)/7)+IF('設定'!$D$9="",0,'設定'!$D$9),16)<8,"P",IF(MOD(INT((($D$3+0*7+3-WEEKDAY($D$3+0*7+3,2)+1)-'設定'!$B$4)/7)+IF('設定'!$D$9="",0,'設定'!$D$9),16)<12,"N","P"))),"")))))) | E9: =IF(OR(E6="",'設定'!$B$9=""),"",IF(COUNTIFS(LeaveName,'設定'!$B$9,LeaveDate,"="&($D$3+0*7+4),LeaveType,"AL")>0,"AL",IF(COUNTIFS(LeaveName,'設定'!$B$9,LeaveDate,"="&($D$3+0*7+4),LeaveType,"SL")>0,"SL",IF('設定'!$B$9="","",IF('設定'!$C$9="S","S",IF('設定'!$C$9="R",IF(MOD(INT((($D$3+0*7+4-WEEKDAY($D$3+0*7+4,2)+1)-'設定'!$B$4)/7)+IF('設定'!$D$9="",0,'設定'!$D$9),16)<4,"A",IF(MOD(INT((($D$3+0*7+4-WEEKDAY($D$3+0*7+4,2)+1)-'設定'!$B$4)/7)+IF('設定'!$D$9="",0,'設定'!$D$9),16)<8,"P",IF(MOD(INT((($D$3+0*7+4-WEEKDAY($D$3+0*7+4,2)+1)-'設定'!$B$4)/7)+IF('設定'!$D$9="",0,'設定'!$D$9),16)<12,"N","P"))),"")))))) | F9: =IF(OR(F6="",'設定'!$B$9=""),"",IF(COUNTIFS(LeaveName,'設定'!$B$9,LeaveDate,"="&($D$3+0*7+5),LeaveType,"AL")>0,"AL",IF(COUNTIFS(LeaveName,'設定'!$B$9,LeaveDate,"="&($D$3+0*7+5),LeaveType,"SL")>0,"SL",IF('設定'!$B$9="","",IF('設定'!$C$9="S","S",IF('設定'!$C$9="R",IF(MOD(INT((($D$3+0*7+5-WEEKDAY($D$3+0*7+5,2)+1)-'設定'!$B$4)/7)+IF('設定'!$D$9="",0,'設定'!$D$9),16)<4,"A",IF(MOD(INT((($D$3+0*7+5-WEEKDAY($D$3+0*7+5,2)+1)-'設定'!$B$4)/7)+IF('設定'!$D$9="",0,'設定'!$D$9),16)<8,"P",IF(MOD(INT((($D$3+0*7+5-WEEKDAY($D$3+0*7+5,2)+1)-'設定'!$B$4)/7)+IF('設定'!$D$9="",0,'設定'!$D$9),16)<12,"N","P"))),"")))))) | G9: =IF(OR(G6="",'設定'!$B$9=""),"",IF(COUNTIFS(LeaveName,'設定'!$B$9,LeaveDate,"="&($D$3+0*7+6),LeaveType,"AL")>0,"AL",IF(COUNTIFS(LeaveName,'設定'!$B$9,LeaveDate,"="&($D$3+0*7+6),LeaveType,"SL")>0,"SL",IF('設定'!$B$9="","",IF('設定'!$C$9="S","S",IF('設定'!$C$9="R",IF(MOD(INT((($D$3+0*7+6-WEEKDAY($D$3+0*7+6,2)+1)-'設定'!$B$4)/7)+IF('設定'!$D$9="",0,'設定'!$D$9),16)<4,"A",IF(MOD(INT((($D$3+0*7+6-WEEKDAY($D$3+0*7+6,2)+1)-'設定'!$B$4)/7)+IF('設定'!$D$9="",0,'設定'!$D$9),16)<8,"P",IF(MOD(INT((($D$3+0*7+6-WEEKDAY($D$3+0*7+6,2)+1)-'設定'!$B$4)/7)+IF('設定'!$D$9="",0,'設定'!$D$9),16)<12,"N","P"))),"")))))) | I9: ='設定'!B9
A10: =IF(OR(A6="",'設定'!$B$10=""),"",IF(COUNTIFS(LeaveName,'設定'!$B$10,LeaveDate,"="&($D$3+0*7+0),LeaveType,"AL")>0,"AL",IF(COUNTIFS(LeaveName,'設定'!$B$10,LeaveDate,"="&($D$3+0*7+0),LeaveType,"SL")>0,"SL",IF('設定'!$B$10="","",IF('設定'!$C$10="S","S",IF('設定'!$C$10="R",IF(MOD(INT((($D$3+0*7+0-WEEKDAY($D$3+0*7+0,2)+1)-'設定'!$B$4)/7)+IF('設定'!$D$10="",0,'設定'!$D$10),16)<4,"A",IF(MOD(INT((($D$3+0*7+0-WEEKDAY($D$3+0*7+0,2)+1)-'設定'!$B$4)/7)+IF('設定'!$D$10="",0,'設定'!$D$10),16)<8,"P",IF(MOD(INT((($D$3+0*7+0-WEEKDAY($D$3+0*7+0,2)+1)-'設定'!$B$4)/7)+IF('設定'!$D$10="",0,'設定'!$D$10),16)<12,"N","P"))),"")))))) | B10: =IF(OR(B6="",'設定'!$B$10=""),"",IF(COUNTIFS(LeaveName,'設定'!$B$10,LeaveDate,"="&($D$3+0*7+1),LeaveType,"AL")>0,"AL",IF(COUNTIFS(LeaveName,'設定'!$B$10,LeaveDate,"="&($D$3+0*7+1),LeaveType,"SL")>0,"SL",IF('設定'!$B$10="","",IF('設定'!$C$10="S","S",IF('設定'!$C$10="R",IF(MOD(INT((($D$3+0*7+1-WEEKDAY($D$3+0*7+1,2)+1)-'設定'!$B$4)/7)+IF('設定'!$D$10="",0,'設定'!$D$10),16)<4,"A",IF(MOD(INT((($D$3+0*7+1-WEEKDAY($D$3+0*7+1,2)+1)-'設定'!$B$4)/7)+IF('設定'!$D$10="",0,'設定'!$D$10),16)<8,"P",IF(MOD(INT((($D$3+0*7+1-WEEKDAY($D$3+0*7+1,2)+1)-'設定'!$B$4)/7)+IF('設定'!$D$10="",0,'設定'!$D$10),16)<12,"N","P"))),"")))))) | C10: =IF(OR(C6="",'設定'!$B$10=""),"",IF(COUNTIFS(LeaveName,'設定'!$B$10,LeaveDate,"="&($D$3+0*7+2),LeaveType,"AL")>0,"AL",IF(COUNTIFS(LeaveName,'設定'!$B$10,LeaveDate,"="&($D$3+0*7+2),LeaveType,"SL")>0,"SL",IF('設定'!$B$10="","",IF('設定'!$C$10="S","S",IF('設定'!$C$10="R",IF(MOD(INT((($D$3+0*7+2-WEEKDAY($D$3+0*7+2,2)+1)-'設定'!$B$4)/7)+IF('設定'!$D$10="",0,'設定'!$D$10),16)<4,"A",IF(MOD(INT((($D$3+0*7+2-WEEKDAY($D$3+0*7+2,2)+1)-'設定'!$B$4)/7)+IF('設定'!$D$10="",0,'設定'!$D$10),16)<8,"P",IF(MOD(INT((($D$3+0*7+2-WEEKDAY($D$3+0*7+2,2)+1)-'設定'!$B$4)/7)+IF('設定'!$D$10="",0,'設定'!$D$10),16)<12,"N","P"))),"")))))) | D10: =IF(OR(D6="",'設定'!$B$10=""),"",IF(COUNTIFS(LeaveName,'設定'!$B$10,LeaveDate,"="&($D$3+0*7+3),LeaveType,"AL")>0,"AL",IF(COUNTIFS(LeaveName,'設定'!$B$10,LeaveDate,"="&($D$3+0*7+3),LeaveType,"SL")>0,"SL",IF('設定'!$B$10="","",IF('設定'!$C$10="S","S",IF('設定'!$C$10="R",IF(MOD(INT((($D$3+0*7+3-WEEKDAY($D$3+0*7+3,2)+1)-'設定'!$B$4)/7)+IF('設定'!$D$10="",0,'設定'!$D$10),16)<4,"A",IF(MOD(INT((($D$3+0*7+3-WEEKDAY($D$3+0*7+3,2)+1)-'設定'!$B$4)/7)+IF('設定'!$D$10="",0,'設定'!$D$10),16)<8,"P",IF(MOD(INT((($D$3+0*7+3-WEEKDAY($D$3+0*7+3,2)+1)-'設定'!$B$4)/7)+IF('設定'!$D$10="",0,'設定'!$D$10),16)<12,"N","P"))),"")))))) | E10: =IF(OR(E6="",'設定'!$B$10=""),"",IF(COUNTIFS(LeaveName,'設定'!$B$10,LeaveDate,"="&($D$3+0*7+4),LeaveType,"AL")>0,"AL",IF(COUNTIFS(LeaveName,'設定'!$B$10,LeaveDate,"="&($D$3+0*7+4),LeaveType,"SL")>0,"SL",IF('設定'!$B$10="","",IF('設定'!$C$10="S","S",IF('設定'!$C$10="R",IF(MOD(INT((($D$3+0*7+4-WEEKDAY($D$3+0*7+4,2)+1)-'設定'!$B$4)/7)+IF('設定'!$D$10="",0,'設定'!$D$10),16)<4,"A",IF(MOD(INT((($D$3+0*7+4-WEEKDAY($D$3+0*7+4,2)+1)-'設定'!$B$4)/7)+IF('設定'!$D$10="",0,'設定'!$D$10),16)<8,"P",IF(MOD(INT((($D$3+0*7+4-WEEKDAY($D$3+0*7+4,2)+1)-'設定'!$B$4)/7)+IF('設定'!$D$10="",0,'設定'!$D$10),16)<12,"N","P"))),"")))))) | F10: =IF(OR(F6="",'設定'!$B$10=""),"",IF(COUNTIFS(LeaveName,'設定'!$B$10,LeaveDate,"="&($D$3+0*7+5),LeaveType,"AL")>0,"AL",IF(COUNTIFS(LeaveName,'設定'!$B$10,LeaveDate,"="&($D$3+0*7+5),LeaveType,"SL")>0,"SL",IF('設定'!$B$10="","",IF('設定'!$C$10="S","S",IF('設定'!$C$10="R",IF(MOD(INT((($D$3+0*7+5-WEEKDAY($D$3+0*7+5,2)+1)-'設定'!$B$4)/7)+IF('設定'!$D$10="",0,'設定'!$D$10),16)<4,"A",IF(MOD(INT((($D$3+0*7+5-WEEKDAY($D$3+0*7+5,2)+1)-'設定'!$B$4)/7)+IF('設定'!$D$10="",0,'設定'!$D$10),16)<8,"P",IF(MOD(INT((($D$3+0*7+5-WEEKDAY($D$3+0*7+5,2)+1)-'設定'!$B$4)/7)+IF('設定'!$D$10="",0,'設定'!$D$10),16)<12,"N","P"))),"")))))) | G10: =IF(OR(G6="",'設定'!$B$10=""),"",IF(COUNTIFS(LeaveName,'設定'!$B$10,LeaveDate,"="&($D$3+0*7+6),LeaveType,"AL")>0,"AL",IF(COUNTIFS(LeaveName,'設定'!$B$10,LeaveDate,"="&($D$3+0*7+6),LeaveType,"SL")>0,"SL",IF('設定'!$B$10="","",IF('設定'!$C$10="S","S",IF('設定'!$C$10="R",IF(MOD(INT((($D$3+0*7+6-WEEKDAY($D$3+0*7+6,2)+1)-'設定'!$B$4)/7)+IF('設定'!$D$10="",0,'設定'!$D$10),16)<4,"A",IF(MOD(INT((($D$3+0*7+6-WEEKDAY($D$3+0*7+6,2)+1)-'設定'!$B$4)/7)+IF('設定'!$D$10="",0,'設定'!$D$10),16)<8,"P",IF(MOD(INT((($D$3+0*7+6-WEEKDAY($D$3+0*7+6,2)+1)-'設定'!$B$4)/7)+IF('設定'!$D$10="",0,'設定'!$D$10),16)<12,"N","P"))),"")))))) | I10: ='設定'!B10
